<?xml version="1.0" ?>
<!-- =================================================================================== -->
<!-- |    This document was autogenerated by xacro from repair_full.urdf.xacro         | -->
<!-- |    EDITING THIS FILE BY HAND IS NOT RECOMMENDED                                 | -->
<!-- =================================================================================== -->
<robot name="repair_full">
  <!-- below this value, Gazebo parser ignores links
To give some  perspective, a grain of sand weights  0.0000045 grams. So this corresponds to less than 1/4 of a grain of sand of
fake inertia -> it is acceptable. -->
  <!-- color -->
  <material name="darkblue">
    <color rgba="0.0 0.3 0.9 1"/>
  </material>
  <material name="darkred">
    <color rgba="0.55 0.0 0.0 1"/>
  </material>
  <material name="dark">
    <color rgba="0.6 0.6 0.6 1"/>
  </material>
  <!-- Reading some parameters from a YAML config file -->
  <material name="wood">
    <color rgba="0.522 0.369 0.259 0.8"/>
  </material>
  <material name="silver_gray">
    <color rgba="0.8 0.8 0.8 0.8"/>
  </material>
  <link name="world">
  </link>
  <joint name="world_joint" type="fixed">
    <parent link="world"/>
    <origin rpy="0 0 0" xyz="0 0 0"/>
    <child link="table_top_link"/>
  </joint>
  <link name="table_top_link">
    <visual>
      <origin xyz="0.98 0.0 0.475"/>
      <geometry>
        <box size="1.5 2.5 0.05"/>
      </geometry>
      <material name="wood"/>
    </visual>
    <collision>
      <origin xyz="0.98 0.0 0.475"/>
      <geometry>
        <box size="1.5 2.5 0.05"/>
      </geometry>
    </collision>
  </link>
  <joint name="leg1_joint" type="fixed">
    <parent link="table_top_link"/>
    <origin rpy="0 0 0" xyz="1.73 1.25 0.5"/>
    <child link="leg1_link"/>
  </joint>
  <link name="leg1_link">
    <visual>
      <origin rpy="0 0 0" xyz="0.0 0.0 -0.25"/>
      <geometry>
        <cylinder length="0.5" radius="0.02"/>
      </geometry>
      <material name="silver_gray"/>
    </visual>
    <collision>
      <origin rpy="0.0 0.0 0.0" xyz="0.0 0.0 -0.25"/>
      <geometry>
        <cylinder length="0.5" radius="0.02"/>
      </geometry>
    </collision>
  </link>
  <joint name="vbar1_joint" type="fixed">
    <parent link="leg1_link"/>
    <origin rpy="0 0 0" xyz="0 0 0.5"/>
    <child link="vbar1_link"/>
  </joint>
  <link name="vbar1_link">
    <visual>
      <origin rpy="0 0 0" xyz="0.0 0.0 0"/>
      <geometry>
        <cylinder length="1.0" radius="0.02"/>
      </geometry>
      <material name="silver_gray"/>
    </visual>
    <collision>
      <origin rpy="0.0 0.0 0.0" xyz="0.0 0.0 0"/>
      <geometry>
        <cylinder length="1.0" radius="0.02"/>
      </geometry>
    </collision>
  </link>
  <joint name="leg2_joint" type="fixed">
    <parent link="table_top_link"/>
    <origin rpy="0 0 0" xyz="0.22999999999999998 1.25 0.5"/>
    <child link="leg2_link"/>
  </joint>
  <link name="leg2_link">
    <visual>
      <origin rpy="0 0 0" xyz="0.0 0.0 -0.25"/>
      <geometry>
        <cylinder length="0.5" radius="0.02"/>
      </geometry>
      <material name="silver_gray"/>
    </visual>
    <collision>
      <origin rpy="0.0 0.0 0.0" xyz="0.0 0.0 -0.25"/>
      <geometry>
        <cylinder length="0.5" radius="0.02"/>
      </geometry>
    </collision>
  </link>
  <joint name="vbar2_joint" type="fixed">
    <parent link="leg2_link"/>
    <origin rpy="0 0 0" xyz="0 0 0.5"/>
    <child link="vbar2_link"/>
  </joint>
  <link name="vbar2_link">
    <visual>
      <origin rpy="0 0 0" xyz="0.0 0.0 0"/>
      <geometry>
        <cylinder length="1.0" radius="0.02"/>
      </geometry>
      <material name="silver_gray"/>
    </visual>
    <collision>
      <origin rpy="0.0 0.0 0.0" xyz="0.0 0.0 0"/>
      <geometry>
        <cylinder length="1.0" radius="0.02"/>
      </geometry>
    </collision>
  </link>
  <joint name="leg3_joint" type="fixed">
    <parent link="table_top_link"/>
    <origin rpy="0 0 0" xyz="1.73 -1.25 0.5"/>
    <child link="leg3_link"/>
  </joint>
  <link name="leg3_link">
    <visual>
      <origin rpy="0 0 0" xyz="0.0 0.0 -0.25"/>
      <geometry>
        <cylinder length="0.5" radius="0.02"/>
      </geometry>
      <material name="silver_gray"/>
    </visual>
    <collision>
      <origin rpy="0.0 0.0 0.0" xyz="0.0 0.0 -0.25"/>
      <geometry>
        <cylinder length="0.5" radius="0.02"/>
      </geometry>
    </collision>
  </link>
  <joint name="vbar3_joint" type="fixed">
    <parent link="leg3_link"/>
    <origin rpy="0 0 0" xyz="0 0 0.5"/>
    <child link="vbar3_link"/>
  </joint>
  <link name="vbar3_link">
    <visual>
      <origin rpy="0 0 0" xyz="0.0 0.0 0"/>
      <geometry>
        <cylinder length="1.0" radius="0.02"/>
      </geometry>
      <material name="silver_gray"/>
    </visual>
    <collision>
      <origin rpy="0.0 0.0 0.0" xyz="0.0 0.0 0"/>
      <geometry>
        <cylinder length="1.0" radius="0.02"/>
      </geometry>
    </collision>
  </link>
  <joint name="leg4_joint" type="fixed">
    <parent link="table_top_link"/>
    <origin rpy="0 0 0" xyz="0.22999999999999998 -1.25 0.5"/>
    <child link="leg4_link"/>
  </joint>
  <link name="leg4_link">
    <visual>
      <origin rpy="0 0 0" xyz="0.0 0.0 -0.25"/>
      <geometry>
        <cylinder length="0.5" radius="0.02"/>
      </geometry>
      <material name="silver_gray"/>
    </visual>
    <collision>
      <origin rpy="0.0 0.0 0.0" xyz="0.0 0.0 -0.25"/>
      <geometry>
        <cylinder length="0.5" radius="0.02"/>
      </geometry>
    </collision>
  </link>
  <joint name="vbar4_joint" type="fixed">
    <parent link="leg4_link"/>
    <origin rpy="0 0 0" xyz="0 0 0.5"/>
    <child link="vbar4_link"/>
  </joint>
  <link name="vbar4_link">
    <visual>
      <origin rpy="0 0 0" xyz="0.0 0.0 0"/>
      <geometry>
        <cylinder length="1.0" radius="0.02"/>
      </geometry>
      <material name="silver_gray"/>
    </visual>
    <collision>
      <origin rpy="0.0 0.0 0.0" xyz="0.0 0.0 0"/>
      <geometry>
        <cylinder length="1.0" radius="0.02"/>
      </geometry>
    </collision>
  </link>
  <joint name="obar1_joint" type="fixed">
    <parent link="vbar1_link"/>
    <origin rpy="0 -1.57079632679 0" xyz="-0.75 0 0.5"/>
    <child link="obar1_link"/>
  </joint>
  <link name="obar1_link">
    <visual>
      <origin rpy="0 0 0" xyz="0.0 0.0 0"/>
      <geometry>
        <cylinder length="1.5" radius="0.02"/>
      </geometry>
      <material name="silver_gray"/>
    </visual>
    <collision>
      <origin rpy="0.0 0.0 0.0" xyz="0.0 0.0 0"/>
      <geometry>
        <cylinder length="1.5" radius="0.02"/>
      </geometry>
    </collision>
  </link>
  <joint name="obar2_joint" type="fixed">
    <parent link="vbar3_link"/>
    <origin rpy="0 -1.57079632679 0" xyz="-0.75 0 0.5"/>
    <child link="obar2_link"/>
  </joint>
  <link name="obar2_link">
    <visual>
      <origin rpy="0 0 0" xyz="0.0 0.0 0"/>
      <geometry>
        <cylinder length="1.5" radius="0.02"/>
      </geometry>
      <material name="silver_gray"/>
    </visual>
    <collision>
      <origin rpy="0.0 0.0 0.0" xyz="0.0 0.0 0"/>
      <geometry>
        <cylinder length="1.5" radius="0.02"/>
      </geometry>
    </collision>
  </link>
  <joint name="obar3_joint" type="fixed">
    <parent link="vbar3_link"/>
    <origin rpy="-1.57079632679 0 0" xyz="0 1.25 0.5"/>
    <child link="obar3_link"/>
  </joint>
  <link name="obar3_link">
    <visual>
      <origin rpy="0 0 0" xyz="0.0 0.0 0"/>
      <geometry>
        <cylinder length="2.5" radius="0.02"/>
      </geometry>
      <material name="silver_gray"/>
    </visual>
    <collision>
      <origin rpy="0.0 0.0 0.0" xyz="0.0 0.0 0"/>
      <geometry>
        <cylinder length="2.5" radius="0.02"/>
      </geometry>
    </collision>
  </link>
  <joint name="obar4_joint" type="fixed">
    <parent link="vbar4_link"/>
    <origin rpy="-1.57079632679 0 0" xyz="0 1.25 0.5"/>
    <child link="obar4_link"/>
  </joint>
  <link name="obar4_link">
    <!-- dummy intertia to make Gazebo urdf2sdf converter work -->
    <visual>
      <origin rpy="0 0 0" xyz="0.0 0.0 0"/>
      <geometry>
        <cylinder length="2.5" radius="0.02"/>
      </geometry>
      <material name="silver_gray"/>
    </visual>
    <collision>
      <origin rpy="0.0 0.0 0.0" xyz="0.0 0.0 0"/>
      <geometry>
        <cylinder length="2.5" radius="0.02"/>
      </geometry>
    </collision>
  </link>
  <joint name="sliding_guide_joint" type="fixed">
    <parent link="obar2_link"/>
    <origin rpy="-1.57079632679 0 0" xyz="0 1.25 0"/>
    <child link="sliding_guide_link"/>
  </joint>
  <link name="sliding_guide_link">
    <visual>
      <origin rpy="0 0 0" xyz="0.0 0.0 0"/>
      <geometry>
        <box size="0.001 0.2 2.5"/>
      </geometry>
      <material name="silver_gray"/>
    </visual>
    <collision>
      <origin rpy="0.0 0.0 0.0" xyz="0.0 0.0 0"/>
      <geometry>
        <cylinder length="2.5" radius="0.02"/>
      </geometry>
    </collision>
  </link>
  <joint name="working_surface_joint" type="fixed">
    <parent link="sliding_guide_link"/>
    <origin rpy="0.0 -1.57079632679 3.14159265359" xyz="-1.0 0 0"/>
    <child link="working_surface_link"/>
  </joint>
  <link name="working_surface_link">
    <!-- Huge inertia (does not matter, is fixed to the world)-->
    <inertial>
      <mass value="1"/>
      <origin xyz="0 0 0"/>
      <inertia ixx="0" ixy="0" ixz="0" iyy="0" iyz="0" izz="0"/>
    </inertial>
  </link>
  <!-- Reading some parameters from a YAML config file -->
  <!-- xbot2 joint device driver-->
  <gazebo>
    <plugin filename="libxbot2_gz_joint_server.so" name="xbot2_gz_joint_server">
      <pid>
        <gain d="5" name="lowpwr_mot" p="50"/>
        <gain d="10" name="small_mot" p="1000"/>
        <gain d="40" name="medium_mot" p="4000"/>
        <gain d="50" name="big_mot" p="8000"/>
        <gain d="10" name="wheel_mot" p="0"/>
        <pid name="arm_1_joint_1" profile="medium_mot"/>
        <pid name="arm_1_joint_2" profile="medium_mot"/>
        <pid name="arm_1_joint_3" profile="medium_mot"/>
        <pid name="arm_1_joint_4" profile="medium_mot"/>
        <pid name="arm_1_joint_5" profile="medium_mot"/>
        <pid name="arm_1_joint_6" profile="medium_mot"/>
        <pid name="arm_1_joint_7" profile="medium_mot"/>
        <pid name="arm_2_joint_1" profile="medium_mot"/>
        <pid name="arm_2_joint_2" profile="medium_mot"/>
        <pid name="arm_2_joint_3" profile="medium_mot"/>
        <pid name="arm_2_joint_4" profile="medium_mot"/>
        <pid name="arm_2_joint_5" profile="medium_mot"/>
        <pid name="arm_2_joint_6" profile="medium_mot"/>
        <pid name="arm_2_joint_7" profile="medium_mot"/>
      </pid>
    </plugin>
  </gazebo>
  <gazebo>
    <plugin filename="libxbot2_gz_ft_server.so" name="xbot2_ft_driver"/>
  </gazebo>
  <joint name="x_joint" type="prismatic">
    <origin rpy="0.0 0.0 0.0" xyz="0.0 0.0 0.3034329527232317"/>
    <parent link="working_surface_link"/>
    <child link="base_link"/>
    <axis xyz="1 0 0"/>
    <limit effort="1000.0" lower="-1.15" upper="1.15" velocity="20.0"/>
  </joint>
  <link name="base_link">
    <!-- torso inertias + stuff attached to the sliding guide -->
    <inertial>
      <mass value="1000000"/>
      <origin xyz="0 0 0"/>
      <inertia ixx="0" ixy="0" ixz="0" iyy="0" iyz="0" izz="0"/>
    </inertial>
  </link>
  <joint name="r_arm_mount_joint" type="fixed">
    <origin rpy="0 0 0" xyz="0.0 -0.2942172496425824 0.0"/>
    <parent link="base_link"/>
    <child link="dummy_r"/>
  </joint>
  <joint name="l_arm_mount_joint" type="fixed">
    <origin rpy="0 0 0" xyz="0.0 0.2942172496425824 0.0"/>
    <parent link="base_link"/>
    <child link="dummy_l"/>
  </joint>
  <link name="dummy_r">
    </link>
  <link name="dummy_l">
    </link>
  <joint name="roll_r" type="fixed">
    <origin rpy="0.09051373592070662 0.0 0.0" xyz="0 0.0 0.0"/>
    <parent link="dummy_r"/>
    <child link="r_arm_mount_frame"/>
  </joint>
  <joint name="roll_l" type="fixed">
    <origin rpy="-0.09051373592070662 0.0 0.0" xyz="0 0.0 0.0"/>
    <parent link="dummy_l"/>
    <child link="l_arm_mount_frame"/>
  </joint>
  <link name="r_arm_mount_frame">
    <!-- dummy intertia to make Gazebo urdf2sdf converter work -->
    <inertial>
      <mass value="1.00000000000001e-06"/>
      <origin xyz="0 0 0"/>
      <inertia ixx="0" ixy="0" ixz="0" iyy="0" iyz="0" izz="0"/>
    </inertial>
  </link>
  <link name="l_arm_mount_frame">
    <!-- dummy intertia to make Gazebo urdf2sdf converter work -->
    <inertial>
      <mass value="1.00000000000001e-06"/>
      <origin xyz="0 0 0"/>
      <inertia ixx="0" ixy="0" ixz="0" iyy="0" iyz="0" izz="0"/>
    </inertial>
  </link>
  <!-- id: 1 for right arm, everything else is considered left arm -->
  <!-- base_link: name of base link a the single arm -->
  <!-- is_sliding_wrist: whether to add a sliding joint along the axis of wrist's second d.o.f.
    (true -> yes), everything else -> no -->
  <!-- show_softhand: whether to use softhand or not at the TCP -->
  <joint name="arm_1_joint_1" type="revolute">
    <origin rpy="1.57079632679 0 0" xyz="0 0 0"/>
    <parent link="r_arm_mount_frame"/>
    <child link="arm_1_link_1"/>
    <axis xyz="0 0 1"/>
    <limit effort="200.0" lower="-2.6179938779916667" upper="2.6179938779916667" velocity="10.0"/>
  </joint>
  <link name="arm_1_link_1">
    <inertial>
      <mass value="2"/>
      <inertia ixx="0.0015" ixy="-9.999999999999999e-05" ixz="0.0" iyy="0.0026999999999999997" iyz="9.999999999999999e-05" izz="0.0028"/>
      <origin xyz="0 0 -0.01"/>
    </inertial>
    <collision name="arm_1_link_1_collision">
      <geometry>
        <mesh filename="package://repair_urdf/meshes/link_1.stl" scale="0.001 0.001 0.001"/>
      </geometry>
      <material name="dark"/>
    </collision>
    <visual name="arm_1_link_1_visual">
      <geometry>
        <mesh filename="package://repair_urdf/meshes/link_1.stl" scale="0.001 0.001 0.001"/>
      </geometry>
      <material name="dark"/>
    </visual>
  </link>
  <joint name="arm_1_joint_2" type="revolute">
    <origin rpy="0 -1.57079632679 -3.14159265359" xyz="0.0385 -0.023 0"/>
    <parent link="arm_1_link_1"/>
    <child link="arm_1_link_2"/>
    <axis xyz="0 0 1"/>
    <limit effort="200.0" lower="-1.3962634015955555" upper="2.1816615649930555" velocity="10.0"/>
  </joint>
  <link name="arm_1_link_2">
    <inertial>
      <mass value="0.4"/>
      <inertia ixx="0.00067" ixy="0.0" ixz="0.00017999999999999998" iyy="0.0009699999999999999" iyz="0.0" izz="0.001"/>
      <origin xyz="0.04 0.0 0.035"/>
    </inertial>
    <collision name="arm_1_link_2_collision">
      <geometry>
        <mesh filename="package://repair_urdf/meshes/link_2.stl" scale="0.001 0.001 0.001"/>
      </geometry>
      <material name="dark"/>
    </collision>
    <visual name="arm_1_link_2_visual">
      <geometry>
        <mesh filename="package://repair_urdf/meshes/link_2.stl" scale="0.001 0.001 0.001"/>
      </geometry>
      <material name="dark"/>
    </visual>
  </link>
  <joint name="arm_1_joint_3" type="revolute">
    <origin rpy="0 1.57079632679 0" xyz="0.005 0 0"/>
    <origin rpy="0 -1.57079632679 -3.14159265359" xyz="0.005 0 0"/>
    <parent link="arm_1_link_2"/>
    <child link="arm_1_link_3"/>
    <axis xyz="0 0 1"/>
    <limit effort="200.0" lower="-2.6179938779916667" upper="2.6179938779916667" velocity="10.0"/>
  </joint>
  <link name="arm_1_link_3">
    <inertial>
      <mass value="3.3"/>
      <inertia ixx="0.024999999999999998" ixy="0.0" ixz="0.0" iyy="0.026" iyz="0.0" izz="0.022"/>
      <origin xyz="0.0 -0.025 0.23"/>
    </inertial>
    <collision name="arm_1_link_3_collision">
      <geometry>
        <mesh filename="package://repair_urdf/meshes/link_3.stl" scale="0.001 0.001 0.001"/>
      </geometry>
      <material name="dark"/>
    </collision>
    <visual name="arm_1_link_3_visual">
      <geometry>
        <mesh filename="package://repair_urdf/meshes/link_3.stl" scale="0.001 0.001 0.001"/>
      </geometry>
      <material name="dark"/>
    </visual>
  </link>
  <joint name="arm_1_joint_4" type="revolute">
    <origin rpy="0 -1.57079632679 -3.14159265359" xyz="0 0.0225 0.36014999999999997"/>
    <parent link="arm_1_link_3"/>
    <child link="arm_1_link_4"/>
    <axis xyz="0 0 1"/>
    <limit effort="200.0" lower="-2.6179938779916667" upper="2.0943951023933334" velocity="10.0"/>
  </joint>
  <link name="arm_1_link_4">
    <inertial>
      <mass value="0.4"/>
      <inertia ixx="0.00067" ixy="0.0" ixz="0.00017999999999999998" iyy="0.0009699999999999999" iyz="0.0" izz="0.001"/>
      <origin xyz="0.04 0.0 0.035"/>
    </inertial>
    <collision name="arm_1_link_4_collision">
      <geometry>
        <mesh filename="package://repair_urdf/meshes/link_4.stl" scale="0.001 0.001 0.001"/>
      </geometry>
      <material name="dark"/>
    </collision>
    <visual name="arm_1_link_4_visual">
      <geometry>
        <mesh filename="package://repair_urdf/meshes/link_4.stl" scale="0.001 0.001 0.001"/>
      </geometry>
      <material name="dark"/>
    </visual>
  </link>
  <joint name="arm_1_joint_5" type="revolute">
    <origin rpy="-1.57079632679 0 -1.57079632679" xyz="0.005 0 0"/>
    <parent link="arm_1_link_4"/>
    <child link="arm_1_link_5"/>
    <axis xyz="0 0 1"/>
    <limit effort="200.0" lower="-2.6179938779916667" upper="2.6179938779916667" velocity="10.0"/>
  </joint>
  <link name="arm_1_link_5">
    <inertial>
      <mass value="2.8"/>
      <inertia ixx="0.032" ixy="0.0" ixz="0.0017" iyy="0.033999999999999996" iyz="0.0" izz="0.028999999999999998"/>
      <origin xyz="-0.005 0.0 0.2"/>
    </inertial>
    <collision name="arm_1_link_5_collision">
      <geometry>
        <mesh filename="package://repair_urdf/meshes/link_5.stl" scale="0.001 0.001 0.001"/>
      </geometry>
      <material name="dark"/>
    </collision>
    <visual name="arm_1_link_5_visual">
      <geometry>
        <mesh filename="package://repair_urdf/meshes/link_5.stl" scale="0.001 0.001 0.001"/>
      </geometry>
      <material name="dark"/>
    </visual>
  </link>
  <joint name="arm_1_joint_6" type="revolute">
    <origin rpy="0 -1.57079632679 0" xyz="0 0 0.321"/>
    <parent link="arm_1_link_5"/>
    <child link="dummy_sliding_wrist1_link"/>
    <axis xyz="0 0 1"/>
    <limit effort="200.0" lower="-2.6179938779916667" upper="2.6179938779916667" velocity="10.0"/>
  </joint>
  <link name="dummy_sliding_wrist1_link">
    
    </link>
  <joint name="dummy_sliding_wrist1_joint" type="fixed">
    <origin rpy="0 0 0" xyz="0.0 0.0 -0.09589076394119754"/>
    <parent link="dummy_sliding_wrist1_link"/>
    <child link="arm_1_link_6"/>
  </joint>
  <link name="arm_1_link_6">
    <inertial>
      <mass value="1.8"/>
      <inertia ixx="0.0017" ixy="0.0" ixz="0.0" iyy="0.0025" iyz="9.999999999999999e-05" izz="0.0026999999999999997"/>
      <origin xyz="0.0 0.0 0.0"/>
    </inertial>
    <collision name="arm_1_link_6_collision">
      <geometry>
        <mesh filename="package://repair_urdf/meshes/link_6.stl" scale="0.001 0.001 0.001"/>
      </geometry>
      <material name="dark"/>
    </collision>
    <visual name="arm_1_link_6_visual">
      <geometry>
        <mesh filename="package://repair_urdf/meshes/link_6.stl" scale="0.001 0.001 0.001"/>
      </geometry>
      <material name="dark"/>
    </visual>
  </link>
  <joint name="arm_1_joint_7" type="revolute">
    <origin rpy="1.57079632679 0 1.57079632679" xyz="0.18 0 0"/>
    <parent link="arm_1_link_6"/>
    <child link="arm_1_link_7"/>
    <axis xyz="0 0 1"/>
    <limit effort="200.0" lower="-2.6179938779916667" upper="2.6179938779916667" velocity="10.0"/>
  </joint>
  <link name="arm_1_link_7">
    <inertial>
      <mass value="1.5"/>
      <inertia ixx="0.024999999999999998" ixy="0.0" ixz="0.0" iyy="0.024999999999999998" iyz="9.999999999999999e-05" izz="0.023"/>
      <origin xyz="0.0 0.0 0.0"/>
    </inertial>
    <collision name="arm_1_link_7_collision">
      <geometry>
        <mesh filename="package://repair_urdf/meshes/link_7.stl" scale="0.001 0.001 0.001"/>
      </geometry>
      <material name="dark"/>
    </collision>
    <visual name="arm_1_link_7_visual">
      <origin rpy="0 0 0" xyz="0 0 0"/>
      <geometry>
        <mesh filename="package://repair_urdf/meshes/link_7.stl" scale="0.001 0.001 0.001"/>
      </geometry>
      <material name="dark"/>
    </visual>
  </link>
  <joint name="arm_1_tcp_joint" type="fixed">
    <origin rpy="0 0 0" xyz="0 0 0"/>
    <parent link="arm_1_link_7"/>
    <child link="arm_1_tcp"/>
  </joint>
  <link name="arm_1_tcp"/>
  <!-- id: 1 for right arm, everything else is considered left arm -->
  <!-- base_link: name of base link a the single arm -->
  <!-- is_sliding_wrist: whether to add a sliding joint along the axis of wrist's second d.o.f.
    (true -> yes), everything else -> no -->
  <!-- show_softhand: whether to use softhand or not at the TCP -->
  <joint name="arm_2_joint_1" type="revolute">
    <origin rpy="-1.57079632679 0 0" xyz="0 0 0"/>
    <parent link="l_arm_mount_frame"/>
    <child link="arm_2_link_1"/>
    <axis xyz="0 0 1"/>
    <limit effort="200.0" lower="-2.6179938779916667" upper="2.6179938779916667" velocity="10.0"/>
  </joint>
  <link name="arm_2_link_1">
    <inertial>
      <mass value="2"/>
      <inertia ixx="0.0015" ixy="-9.999999999999999e-05" ixz="0.0" iyy="0.0026999999999999997" iyz="9.999999999999999e-05" izz="0.0028"/>
      <origin xyz="0 0 -0.01"/>
    </inertial>
    <collision name="arm_2_link_1_collision">
      <geometry>
        <mesh filename="package://repair_urdf/meshes/link_1_mirror.stl" scale="0.001 0.001 0.001"/>
      </geometry>
      <material name="dark"/>
    </collision>
    <visual name="arm_2_link_1_visual">
      <geometry>
        <mesh filename="package://repair_urdf/meshes/link_1_mirror.stl" scale="0.001 0.001 0.001"/>
      </geometry>
      <material name="dark"/>
    </visual>
  </link>
  <joint name="arm_2_joint_2" type="revolute">
    <origin rpy="0 -1.57079632679 -3.14159265359" xyz="0.0385 0.023 0"/>
    <parent link="arm_2_link_1"/>
    <child link="arm_2_link_2"/>
    <axis xyz="0 0 1"/>
    <limit effort="200.0" lower="-1.3962634015955555" upper="2.1816615649930555" velocity="10.0"/>
  </joint>
  <link name="arm_2_link_2">
    <inertial>
      <mass value="0.4"/>
      <inertia ixx="0.00067" ixy="0.0" ixz="0.00017999999999999998" iyy="0.0009699999999999999" iyz="0.0" izz="0.001"/>
      <origin xyz="0.04 0.0 0.035"/>
    </inertial>
    <collision name="arm_2_link_2_collision">
      <geometry>
        <mesh filename="package://repair_urdf/meshes/link_2.stl" scale="0.001 0.001 0.001"/>
      </geometry>
      <material name="dark"/>
    </collision>
    <visual name="arm_2_link_2_visual">
      <geometry>
        <mesh filename="package://repair_urdf/meshes/link_2.stl" scale="0.001 0.001 0.001"/>
      </geometry>
      <material name="dark"/>
    </visual>
  </link>
  <joint name="arm_2_joint_3" type="revolute">
    <origin rpy="0 -1.57079632679 -3.14159265359" xyz="0.005 0 0"/>
    <parent link="arm_2_link_2"/>
    <child link="arm_2_link_3"/>
    <axis xyz="0 0 1"/>
    <limit effort="200.0" lower="-2.6179938779916667" upper="2.6179938779916667" velocity="10.0"/>
  </joint>
  <link name="arm_2_link_3">
    <inertial>
      <mass value="3.3"/>
      <inertia ixx="0.024999999999999998" ixy="0.0" ixz="0.0" iyy="0.026" iyz="0.0" izz="0.022"/>
      <origin xyz="0.0 -0.025 0.23"/>
    </inertial>
    <collision name="arm_2_link_3_collision">
      <geometry>
        <mesh filename="package://repair_urdf/meshes/link_3.stl" scale="0.001 0.001 0.001"/>
      </geometry>
      <material name="dark"/>
    </collision>
    <visual name="arm_2_link_3_visual">
      <geometry>
        <mesh filename="package://repair_urdf/meshes/link_3.stl" scale="0.001 0.001 0.001"/>
      </geometry>
      <material name="dark"/>
    </visual>
  </link>
  <joint name="arm_2_joint_4" type="revolute">
    <origin rpy="0 -1.57079632679 -3.14159265359" xyz="0 0.0225 0.36014999999999997"/>
    <parent link="arm_2_link_3"/>
    <child link="arm_2_link_4"/>
    <axis xyz="0 0 1"/>
    <limit effort="200.0" lower="-2.6179938779916667" upper="2.0943951023933334" velocity="10.0"/>
  </joint>
  <link name="arm_2_link_4">
    <inertial>
      <mass value="0.4"/>
      <inertia ixx="0.00067" ixy="0.0" ixz="0.00017999999999999998" iyy="0.0009699999999999999" iyz="0.0" izz="0.001"/>
      <origin xyz="0.04 0.0 0.035"/>
    </inertial>
    <collision name="arm_2_link_4_collision">
      <geometry>
        <mesh filename="package://repair_urdf/meshes/link_4.stl" scale="0.001 0.001 0.001"/>
      </geometry>
      <material name="dark"/>
    </collision>
    <visual name="arm_2_link_4_visual">
      <geometry>
        <mesh filename="package://repair_urdf/meshes/link_4.stl" scale="0.001 0.001 0.001"/>
      </geometry>
      <material name="dark"/>
    </visual>
  </link>
  <joint name="arm_2_joint_5" type="revolute">
    <origin rpy="-1.57079632679 0 -1.57079632679" xyz="0.005 0 0"/>
    <parent link="arm_2_link_4"/>
    <child link="arm_2_link_5"/>
    <axis xyz="0 0 1"/>
    <limit effort="200.0" lower="-2.6179938779916667" upper="2.6179938779916667" velocity="10.0"/>
  </joint>
  <link name="arm_2_link_5">
    <inertial>
      <mass value="2.8"/>
      <inertia ixx="0.032" ixy="0.0" ixz="0.0017" iyy="0.033999999999999996" iyz="0.0" izz="0.028999999999999998"/>
      <origin xyz="-0.005 0.0 0.2"/>
    </inertial>
    <collision name="arm_2_link_5_collision">
      <geometry>
        <mesh filename="package://repair_urdf/meshes/link_5.stl" scale="0.001 0.001 0.001"/>
      </geometry>
      <material name="dark"/>
    </collision>
    <visual name="arm_2_link_5_visual">
      <geometry>
        <mesh filename="package://repair_urdf/meshes/link_5.stl" scale="0.001 0.001 0.001"/>
      </geometry>
      <material name="dark"/>
    </visual>
  </link>
  <joint name="arm_2_joint_6" type="revolute">
    <origin rpy="0 -1.57079632679 0" xyz="0 0 0.321"/>
    <parent link="arm_2_link_5"/>
    <child link="dummy_sliding_wrist2_link"/>
    <axis xyz="0 0 1"/>
    <limit effort="200.0" lower="-2.6179938779916667" upper="2.6179938779916667" velocity="10.0"/>
  </joint>
  <link name="dummy_sliding_wrist2_link">
    
    </link>
  <joint name="dummy_sliding_wrist2_joint" type="fixed">
    <origin rpy="0 0 0" xyz="0.0 0.0 -0.09589076394119754"/>
    <parent link="dummy_sliding_wrist2_link"/>
    <child link="arm_2_link_6"/>
  </joint>
  <link name="arm_2_link_6">
    <inertial>
      <mass value="1.8"/>
      <inertia ixx="0.0017" ixy="0.0" ixz="0.0" iyy="0.0025" iyz="9.999999999999999e-05" izz="0.0026999999999999997"/>
      <origin xyz="0.0 0.0 0.0"/>
    </inertial>
    <collision name="arm_2_link_6_collision">
      <geometry>
        <mesh filename="package://repair_urdf/meshes/link_6.stl" scale="0.001 0.001 0.001"/>
      </geometry>
      <material name="dark"/>
    </collision>
    <visual name="arm_2_link_6_visual">
      <geometry>
        <mesh filename="package://repair_urdf/meshes/link_6.stl" scale="0.001 0.001 0.001"/>
      </geometry>
      <material name="dark"/>
    </visual>
  </link>
  <joint name="arm_2_joint_7" type="revolute">
    <origin rpy="-1.57079632679 3.14159265359 -1.57079632679" xyz="0.18 0 0"/>
    <!-- <origin xyz="${180.000 * mmTom} 0 0" rpy="${-PI_2} 0 ${-PI_2}"/> -->
    <parent link="arm_2_link_6"/>
    <child link="arm_2_link_7"/>
    <axis xyz="0 0 1"/>
    <limit effort="200.0" lower="-2.6179938779916667" upper="2.6179938779916667" velocity="10.0"/>
  </joint>
  <link name="arm_2_link_7">
    <inertial>
      <mass value="1.5"/>
      <inertia ixx="0.024999999999999998" ixy="0.0" ixz="0.0" iyy="0.024999999999999998" iyz="9.999999999999999e-05" izz="0.023"/>
      <origin xyz="0.0 0.0 0.0"/>
    </inertial>
    <collision name="arm_2_link_7_collision">
      <geometry>
        <mesh filename="package://repair_urdf/meshes/link_7.stl" scale="0.001 0.001 0.001"/>
      </geometry>
      <material name="dark"/>
    </collision>
    <visual name="arm_2_link_7_visual">
      <origin rpy="0 0 0" xyz="0 0 0"/>
      <geometry>
        <mesh filename="package://repair_urdf/meshes/link_7.stl" scale="0.001 0.001 0.001"/>
      </geometry>
      <material name="dark"/>
    </visual>
  </link>
  <joint name="arm_2_tcp_joint" type="fixed">
    <origin rpy="0 0 0" xyz="0 0 0"/>
    <parent link="arm_2_link_7"/>
    <child link="arm_2_tcp"/>
  </joint>
  <link name="arm_2_tcp"/>
</robot>
