<?xml version="1.0" ?>
<!-- =================================================================================== -->
<!-- |    This document was autogenerated by xacro from /home/andreap/hhcm_ws/src/iit-repair-ros-pkg/repair_urdf/urdf/repair_full.urdf.xacro | -->
<!-- |    EDITING THIS FILE BY HAND IS NOT RECOMMENDED                                 | -->
<!-- =================================================================================== -->
<robot name="repair_full">
  <!-- below this value, Gazebo parser ignores links
To give some  perspective, a grain of sand weights  0.0000045 grams. So this corresponds to less than 1/4 of a grain of sand of
fake inertia -> it is acceptable. -->
  <!-- color -->
  <material name="darkblue">
    <color rgba="0.0 0.3 0.9 1"/>
  </material>
  <material name="darkred">
    <color rgba="0.55 0.0 0.0 1"/>
  </material>
  <material name="dark">
    <color rgba="0.6 0.6 0.6 1"/>
  </material>
  <!-- Reading some parameters from a YAML config file -->
  <material name="wood">
    <color rgba="0.522 0.369 0.259 0.8"/>
  </material>
  <material name="silver_gray">
    <color rgba="0.8 0.8 0.8 0.8"/>
  </material>
  <link name="world">
  </link>
  <joint name="world_joint" type="fixed">
    <parent link="world"/>
    <origin rpy="0 0 0" xyz="0 0 0"/>
    <child link="table_top_link"/>
  </joint>
  <link name="table_top_link">
    <visual>
      <origin xyz="0.98 0.0 0.475"/>
      <geometry>
        <box size="1.5 2.5 0.05"/>
      </geometry>
      <material name="wood"/>
    </visual>
    <collision>
      <origin xyz="0.98 0.0 0.475"/>
      <geometry>
        <box size="1.5 2.5 0.05"/>
      </geometry>
    </collision>
  </link>
  <joint name="leg1_joint" type="fixed">
    <parent link="table_top_link"/>
    <origin rpy="0 0 0" xyz="1.73 1.25 0.5"/>
    <child link="leg1_link"/>
  </joint>
  <link name="leg1_link">
    <visual>
      <origin rpy="0 0 0" xyz="0.0 0.0 -0.25"/>
      <geometry>
        <cylinder length="0.5" radius="0.02"/>
      </geometry>
      <material name="silver_gray"/>
    </visual>
    <collision>
      <origin rpy="0.0 0.0 0.0" xyz="0.0 0.0 -0.25"/>
      <geometry>
        <cylinder length="0.5" radius="0.02"/>
      </geometry>
    </collision>
  </link>
  <joint name="vbar1_joint" type="fixed">
    <parent link="leg1_link"/>
    <origin rpy="0 0 0" xyz="0 0 0.5"/>
    <child link="vbar1_link"/>
  </joint>
  <link name="vbar1_link">
    <visual>
      <origin rpy="0 0 0" xyz="0.0 0.0 0"/>
      <geometry>
        <cylinder length="1.0" radius="0.02"/>
      </geometry>
      <material name="silver_gray"/>
    </visual>
    <collision>
      <origin rpy="0.0 0.0 0.0" xyz="0.0 0.0 0"/>
      <geometry>
        <cylinder length="1.0" radius="0.02"/>
      </geometry>
    </collision>
  </link>
  <joint name="leg2_joint" type="fixed">
    <parent link="table_top_link"/>
    <origin rpy="0 0 0" xyz="0.22999999999999998 1.25 0.5"/>
    <child link="leg2_link"/>
  </joint>
  <link name="leg2_link">
    <visual>
      <origin rpy="0 0 0" xyz="0.0 0.0 -0.25"/>
      <geometry>
        <cylinder length="0.5" radius="0.02"/>
      </geometry>
      <material name="silver_gray"/>
    </visual>
    <collision>
      <origin rpy="0.0 0.0 0.0" xyz="0.0 0.0 -0.25"/>
      <geometry>
        <cylinder length="0.5" radius="0.02"/>
      </geometry>
    </collision>
  </link>
  <joint name="vbar2_joint" type="fixed">
    <parent link="leg2_link"/>
    <origin rpy="0 0 0" xyz="0 0 0.5"/>
    <child link="vbar2_link"/>
  </joint>
  <link name="vbar2_link">
    <visual>
      <origin rpy="0 0 0" xyz="0.0 0.0 0"/>
      <geometry>
        <cylinder length="1.0" radius="0.02"/>
      </geometry>
      <material name="silver_gray"/>
    </visual>
    <collision>
      <origin rpy="0.0 0.0 0.0" xyz="0.0 0.0 0"/>
      <geometry>
        <cylinder length="1.0" radius="0.02"/>
      </geometry>
    </collision>
  </link>
  <joint name="leg3_joint" type="fixed">
    <parent link="table_top_link"/>
    <origin rpy="0 0 0" xyz="1.73 -1.25 0.5"/>
    <child link="leg3_link"/>
  </joint>
  <link name="leg3_link">
    <visual>
      <origin rpy="0 0 0" xyz="0.0 0.0 -0.25"/>
      <geometry>
        <cylinder length="0.5" radius="0.02"/>
      </geometry>
      <material name="silver_gray"/>
    </visual>
    <collision>
      <origin rpy="0.0 0.0 0.0" xyz="0.0 0.0 -0.25"/>
      <geometry>
        <cylinder length="0.5" radius="0.02"/>
      </geometry>
    </collision>
  </link>
  <joint name="vbar3_joint" type="fixed">
    <parent link="leg3_link"/>
    <origin rpy="0 0 0" xyz="0 0 0.5"/>
    <child link="vbar3_link"/>
  </joint>
  <link name="vbar3_link">
    <visual>
      <origin rpy="0 0 0" xyz="0.0 0.0 0"/>
      <geometry>
        <cylinder length="1.0" radius="0.02"/>
      </geometry>
      <material name="silver_gray"/>
    </visual>
    <collision>
      <origin rpy="0.0 0.0 0.0" xyz="0.0 0.0 0"/>
      <geometry>
        <cylinder length="1.0" radius="0.02"/>
      </geometry>
    </collision>
  </link>
  <joint name="leg4_joint" type="fixed">
    <parent link="table_top_link"/>
    <origin rpy="0 0 0" xyz="0.22999999999999998 -1.25 0.5"/>
    <child link="leg4_link"/>
  </joint>
  <link name="leg4_link">
    <visual>
      <origin rpy="0 0 0" xyz="0.0 0.0 -0.25"/>
      <geometry>
        <cylinder length="0.5" radius="0.02"/>
      </geometry>
      <material name="silver_gray"/>
    </visual>
    <collision>
      <origin rpy="0.0 0.0 0.0" xyz="0.0 0.0 -0.25"/>
      <geometry>
        <cylinder length="0.5" radius="0.02"/>
      </geometry>
    </collision>
  </link>
  <joint name="vbar4_joint" type="fixed">
    <parent link="leg4_link"/>
    <origin rpy="0 0 0" xyz="0 0 0.5"/>
    <child link="vbar4_link"/>
  </joint>
  <link name="vbar4_link">
    <visual>
      <origin rpy="0 0 0" xyz="0.0 0.0 0"/>
      <geometry>
        <cylinder length="1.0" radius="0.02"/>
      </geometry>
      <material name="silver_gray"/>
    </visual>
    <collision>
      <origin rpy="0.0 0.0 0.0" xyz="0.0 0.0 0"/>
      <geometry>
        <cylinder length="1.0" radius="0.02"/>
      </geometry>
    </collision>
  </link>
  <joint name="obar1_joint" type="fixed">
    <parent link="vbar1_link"/>
    <origin rpy="0 -1.57079632679 0" xyz="-0.75 0 0.5"/>
    <child link="obar1_link"/>
  </joint>
  <link name="obar1_link">
    <visual>
      <origin rpy="0 0 0" xyz="0.0 0.0 0"/>
      <geometry>
        <cylinder length="1.5" radius="0.02"/>
      </geometry>
      <material name="silver_gray"/>
    </visual>
    <collision>
      <origin rpy="0.0 0.0 0.0" xyz="0.0 0.0 0"/>
      <geometry>
        <cylinder length="1.5" radius="0.02"/>
      </geometry>
    </collision>
  </link>
  <joint name="obar2_joint" type="fixed">
    <parent link="vbar3_link"/>
    <origin rpy="0 -1.57079632679 0" xyz="-0.75 0 0.5"/>
    <child link="obar2_link"/>
  </joint>
  <link name="obar2_link">
    <visual>
      <origin rpy="0 0 0" xyz="0.0 0.0 0"/>
      <geometry>
        <cylinder length="1.5" radius="0.02"/>
      </geometry>
      <material name="silver_gray"/>
    </visual>
    <collision>
      <origin rpy="0.0 0.0 0.0" xyz="0.0 0.0 0"/>
      <geometry>
        <cylinder length="1.5" radius="0.02"/>
      </geometry>
    </collision>
  </link>
  <joint name="obar3_joint" type="fixed">
    <parent link="vbar3_link"/>
    <origin rpy="-1.57079632679 0 0" xyz="0 1.25 0.5"/>
    <child link="obar3_link"/>
  </joint>
  <link name="obar3_link">
    <visual>
      <origin rpy="0 0 0" xyz="0.0 0.0 0"/>
      <geometry>
        <cylinder length="2.5" radius="0.02"/>
      </geometry>
      <material name="silver_gray"/>
    </visual>
    <collision>
      <origin rpy="0.0 0.0 0.0" xyz="0.0 0.0 0"/>
      <geometry>
        <cylinder length="2.5" radius="0.02"/>
      </geometry>
    </collision>
  </link>
  <joint name="obar4_joint" type="fixed">
    <parent link="vbar4_link"/>
    <origin rpy="-1.57079632679 0 0" xyz="0 1.25 0.5"/>
    <child link="obar4_link"/>
  </joint>
  <link name="obar4_link">
    <!-- dummy intertia to make Gazebo urdf2sdf converter work -->
    <visual>
      <origin rpy="0 0 0" xyz="0.0 0.0 0"/>
      <geometry>
        <cylinder length="2.5" radius="0.02"/>
      </geometry>
      <material name="silver_gray"/>
    </visual>
    <collision>
      <origin rpy="0.0 0.0 0.0" xyz="0.0 0.0 0"/>
      <geometry>
        <cylinder length="2.5" radius="0.02"/>
      </geometry>
    </collision>
  </link>
  <joint name="sliding_guide_joint" type="fixed">
    <parent link="obar2_link"/>
    <origin rpy="-1.57079632679 0 0" xyz="0 1.25 0"/>
    <child link="sliding_guide_link"/>
  </joint>
  <link name="sliding_guide_link">
    <visual>
      <origin rpy="0 0 0" xyz="0.0 0.0 0"/>
      <geometry>
        <box size="0.001 0.2 2.5"/>
      </geometry>
      <material name="silver_gray"/>
    </visual>
    <collision>
      <origin rpy="0.0 0.0 0.0" xyz="0.0 0.0 0"/>
      <geometry>
        <cylinder length="2.5" radius="0.02"/>
      </geometry>
    </collision>
  </link>
  <joint name="working_surface_joint" type="fixed">
    <parent link="sliding_guide_link"/>
    <origin rpy="0.0 -1.57079632679 3.14159265359" xyz="-1.0 0 0"/>
    <child link="working_surface_link"/>
  </joint>
  <link name="working_surface_link">
    <!-- Huge inertia (does not matter, is fixed to the world)-->
    <inertial>
      <mass value="1000"/>
      <origin xyz="0 0 0"/>
      <inertia ixx="0" ixy="0" ixz="0" iyy="0" iyz="0" izz="0"/>
    </inertial>
  </link>
  <gazebo reference="table_top_link">
    <material>Gazebo/Wood </material>
  </gazebo>
  <gazebo reference="leg1_link">
    <material>Gazebo/Grey </material>
  </gazebo>
  <gazebo reference="leg2_link">
    <material>Gazebo/Grey </material>
  </gazebo>
  <gazebo reference="leg3_link">
    <material>Gazebo/Grey </material>
  </gazebo>
  <gazebo reference="leg4_link">
    <material>Gazebo/Grey </material>
  </gazebo>
  <gazebo reference="vbar1_link">
    <material>Gazebo/Grey </material>
  </gazebo>
  <gazebo reference="vbar2_link">
    <material>Gazebo/Grey </material>
  </gazebo>
  <gazebo reference="vbar3_link">
    <material>Gazebo/Grey </material>
  </gazebo>
  <gazebo reference="vbar4_link">
    <material>Gazebo/Grey </material>
  </gazebo>
  <gazebo reference="obar1_link">
    <material>Gazebo/Grey </material>
  </gazebo>
  <gazebo reference="obar2_link">
    <material>Gazebo/Grey </material>
  </gazebo>
  <gazebo reference="obar3_link">
    <material>Gazebo/Grey </material>
  </gazebo>
  <gazebo reference="obar4_link">
    <material>Gazebo/Grey </material>
  </gazebo>
  <gazebo reference="sliding_guide_link">
    <material>Gazebo/Grey </material>
  </gazebo>
  <!-- Reading some parameters from a YAML config file -->
  <!-- <xacro:if value="$(arg gen_coll)">

    <xacro:include filename="$(find repair_urdf)/urdf/repair_torso_coll_params.urdf.xacro"/>

    <xacro:include filename="$(find repair_urdf)/urdf/repair_torso_coll.urdf.xacro"/>

    <xacro:repair_torso_coll /> 

</xacro:if> -->
  <joint name="x_joint" type="prismatic">
    <origin rpy="0.0 0.0 0.0" xyz="0.0 0.0 0.0"/>
    <parent link="working_surface_link"/>
    <child link="dummy_link"/>
    <axis xyz="1 0 0"/>
    <limit effort="1000.0" lower="-1.15" upper="1.15" velocity="20.0"/>
  </joint>
  <link name="dummy_link">
    </link>
  <joint name="z_joint" type="prismatic">
    <origin rpy="0.0 0.0 0.0" xyz="0.0 0.0 0.0"/>
    <parent link="dummy_link"/>
    <child link="base_link"/>
    <axis xyz="0 0 1"/>
    <limit effort="1000.0" lower="0.3" upper="2" velocity="20.0"/>
  </joint>
  <!-- RePAIR assembly (two arms) -->
  <link name="base_link">
    <!-- torso inertias + stuff attached to the sliding guide -->
    <inertial>
      <mass value="5.0"/>
      <origin xyz="0 0 0"/>
      <inertia ixx="0" ixy="0" ixz="0" iyy="0" iyz="0" izz="0"/>
    </inertial>
  </link>
  <link name="dummy_r">
    </link>
  <link name="dummy_l">
    </link>
  <joint name="r_arm_mount_joint" type="prismatic">
    <origin rpy="0 0 0" xyz="0.0 0.0 0.0"/>
    <parent link="base_link"/>
    <child link="dummy_r"/>
    <axis xyz="0 -1 0"/>
    <limit effort="1000.0" lower="0.21" upper="0.5" velocity="20.0"/>
  </joint>
  <joint name="l_arm_mount_joint" type="prismatic">
    <origin rpy="0 0 0" xyz="0.0 0.0 0.0"/>
    <parent link="base_link"/>
    <child link="dummy_l"/>
    <axis xyz="0 1 0"/>
    <limit effort="1000.0" lower="0.21" upper="0.5" velocity="20.0"/>
  </joint>
  <joint name="roll_r" type="revolute">
    <origin rpy="0.0 0.0 0.0" xyz="0.0 0.0 0.0"/>
    <parent link="dummy_r"/>
    <child link="r_arm_mount_frame"/>
    <axis xyz="1 0 0"/>
    <limit effort="0.0" lower="-1.047197551196598" upper="1.57079632679" velocity="0.0"/>
  </joint>
  <joint name="roll_l" type="revolute">
    <origin rpy="0.0 0.0 0.0" xyz="0.0 0.0 0.0"/>
    <parent link="dummy_l"/>
    <child link="l_arm_mount_frame"/>
    <axis xyz="-1 0 0"/>
    <limit effort="0.0" lower="-1.047197551196598" upper="1.57079632679" velocity="0.0"/>
  </joint>
  <link name="r_arm_mount_frame">
    
    </link>
  <link name="l_arm_mount_frame">
    </link>
  <joint name="arm_1_link_1_coll_joint" type="fixed">
    <origin rpy="0 0 0" xyz="0.0 0.0 0.0"/>
    <parent link="arm_1_link_1"/>
    <child link="arm_1_link1_coll"/>
  </joint>
  <link name="arm_1_link1_coll">
    <visual name="arm_1_link1_coll_visual">
      <origin rpy="0 0 0" xyz="0 0 0"/>
      <geometry>
        <sphere radius="0.07"/>
      </geometry>
      <material name="darkred"/>
    </visual>
  </link>
  <joint name="arm_1_link_2_coll_joint" type="fixed">
    <origin rpy="0 0 0" xyz="0.0 0 0.03"/>
    <parent link="arm_1_link_2"/>
    <child link="arm_1_link2_coll"/>
  </joint>
  <link name="arm_1_link2_coll">
    <visual name="arm_1_link2_coll_visual">
      <origin rpy="0 0 0" xyz="0 0 0"/>
      <geometry>
        <sphere radius="0.053"/>
      </geometry>
      <material name="darkred"/>
    </visual>
  </link>
  <joint name="arm_1_link_3_coll_joint" type="fixed">
    <origin rpy="0 0 0" xyz="0.0 0.0 0.22"/>
    <parent link="arm_1_link_3"/>
    <child link="arm_1_link3_coll"/>
  </joint>
  <link name="arm_1_link3_coll">
    <visual name="arm_1_link3_coll_visual">
      <origin rpy="0 0 0" xyz="0 0 0"/>
      <geometry>
        <sphere radius="0.08"/>
      </geometry>
      <material name="darkred"/>
    </visual>
  </link>
  <joint name="arm_1_link_4_coll_joint" type="fixed">
    <origin rpy="0 0 0" xyz="0.1 0.0 0.0"/>
    <parent link="arm_1_link_4"/>
    <child link="arm_1_link4_coll"/>
  </joint>
  <link name="arm_1_link4_coll">
    <visual name="arm_1_link4_coll_visual">
      <origin rpy="0 0 0" xyz="0 0 0"/>
      <geometry>
        <sphere radius="0.08"/>
      </geometry>
      <material name="darkred"/>
    </visual>
  </link>
  <joint name="arm_1_link_5_coll_joint" type="prismatic">
    <origin rpy="0 0 0" xyz="-0.1 0.0 0.321"/>
    <parent link="arm_1_link_5"/>
    <child link="arm_1_link5_coll"/>
    <limit effort="200.0" lower="0" upper="0.1" velocity="10.0"/>
    <axis xyz="1 0 0"/>
  </joint>
  <link name="arm_1_link5_coll">
    <visual name="arm_1_link5_coll_visual">
      <geometry>
        <sphere radius="0.06"/>
      </geometry>
      <material name="darkred"/>
    </visual>
  </link>
  <joint name="arm_1_link_6_coll_joint" type="fixed">
    <origin rpy="0 0 0" xyz="0.0 0.0 0.0"/>
    <parent link="arm_1_link_6"/>
    <child link="arm_1_link6_coll"/>
  </joint>
  <link name="arm_1_link6_coll">
    <visual name="arm_1_link6_coll_visual">
      <geometry>
        <sphere radius="0.07"/>
      </geometry>
      <material name="darkred"/>
    </visual>
  </link>
  <joint name="arm_1_link7_coll_joint" type="fixed">
    <origin rpy="0 0 0" xyz="0.0 0.0 -0.06"/>
    <parent link="arm_1_link_7"/>
    <child link="arm_1_link7_coll"/>
  </joint>
  <link name="arm_1_link7_coll">
    <visual name="arm_1_link7_coll_visual">
      <geometry>
        <sphere radius="0.05"/>
      </geometry>
      <material name="darkred"/>
    </visual>
  </link>
  <!-- id: 1 for right arm, everything else is considered left arm -->
  <!-- base_link: name of base link a the single arm -->
  <!-- is_sliding_wrist: whether to add a sliding joint along the axis of wrist's second d.o.f.
    (true -> yes), everything else -> no -->
  <joint name="arm_1_joint_1" type="revolute">
    <origin rpy="1.57079632679 0 0" xyz="0 0 0"/>
    <parent link="r_arm_mount_frame"/>
    <child link="arm_1_link_1"/>
    <axis xyz="0 0 1"/>
    <limit effort="200.0" lower="-2.6179938779916667" upper="2.6179938779916667" velocity="10.0"/>
  </joint>
  <link name="arm_1_link_1">
    <inertial>
      <mass value="2"/>
      <inertia ixx="0.0015" ixy="-9.999999999999999e-05" ixz="0.0" iyy="0.0026999999999999997" iyz="9.999999999999999e-05" izz="0.0028"/>
      <origin xyz="0 0 -0.01"/>
    </inertial>
    <collision name="arm_1_link_1_collision">
      <geometry>
        <mesh filename="package://repair_urdf/meshes/base_meshes/link_1.stl" scale="0.001 0.001 0.001"/>
      </geometry>
      <material name="dark"/>
    </collision>
    <visual name="arm_1_link_1_visual">
      <geometry>
        <mesh filename="package://repair_urdf/meshes/base_meshes/link_1.stl" scale="0.001 0.001 0.001"/>
      </geometry>
      <material name="dark"/>
    </visual>
  </link>
  <joint name="arm_1_joint_2" type="revolute">
    <origin rpy="0 -1.57079632679 -3.14159265359" xyz="0.0385 -0.023 0"/>
    <parent link="arm_1_link_1"/>
    <child link="arm_1_link_2"/>
    <axis xyz="0 0 1"/>
    <limit effort="200.0" lower="-1.3962634015955555" upper="2.1816615649930555" velocity="10.0"/>
  </joint>
  <link name="arm_1_link_2">
    <inertial>
      <mass value="0.4"/>
      <inertia ixx="0.00067" ixy="0.0" ixz="0.00017999999999999998" iyy="0.0009699999999999999" iyz="0.0" izz="0.001"/>
      <origin xyz="0.04 0.0 0.035"/>
    </inertial>
    <collision name="arm_1_link_2_collision">
      <geometry>
        <mesh filename="package://repair_urdf/meshes/base_meshes/link_2.stl" scale="0.001 0.001 0.001"/>
      </geometry>
      <material name="dark"/>
    </collision>
    <visual name="arm_1_link_2_visual">
      <geometry>
        <mesh filename="package://repair_urdf/meshes/base_meshes/link_2.stl" scale="0.001 0.001 0.001"/>
      </geometry>
      <material name="dark"/>
    </visual>
  </link>
  <joint name="arm_1_joint_3" type="revolute">
    <origin rpy="0 1.57079632679 0" xyz="0.005 0 0"/>
    <origin rpy="0 -1.57079632679 -3.14159265359" xyz="0.005 0 0"/>
    <parent link="arm_1_link_2"/>
    <child link="arm_1_link_3"/>
    <axis xyz="0 0 1"/>
    <limit effort="200.0" lower="-2.6179938779916667" upper="2.6179938779916667" velocity="10.0"/>
  </joint>
  <link name="arm_1_link_3">
    <inertial>
      <mass value="3.3"/>
      <inertia ixx="0.024999999999999998" ixy="0.0" ixz="0.0" iyy="0.026" iyz="0.0" izz="0.022"/>
      <origin xyz="0.0 -0.025 0.23"/>
    </inertial>
    <collision name="arm_1_link_3_collision">
      <geometry>
        <mesh filename="package://repair_urdf/meshes/base_meshes/link_3.stl" scale="0.001 0.001 0.001"/>
      </geometry>
      <material name="dark"/>
    </collision>
    <visual name="arm_1_link_3_visual">
      <geometry>
        <mesh filename="package://repair_urdf/meshes/base_meshes/link_3.stl" scale="0.001 0.001 0.001"/>
      </geometry>
      <material name="dark"/>
    </visual>
  </link>
  <joint name="arm_1_joint_4" type="revolute">
    <origin rpy="0 -1.57079632679 -3.14159265359" xyz="0 0.0225 0.36014999999999997"/>
    <parent link="arm_1_link_3"/>
    <child link="arm_1_link_4"/>
    <axis xyz="0 0 1"/>
    <limit effort="200.0" lower="-2.6179938779916667" upper="2.0943951023933334" velocity="10.0"/>
  </joint>
  <link name="arm_1_link_4">
    <inertial>
      <mass value="0.4"/>
      <inertia ixx="0.00067" ixy="0.0" ixz="0.00017999999999999998" iyy="0.0009699999999999999" iyz="0.0" izz="0.001"/>
      <origin xyz="0.04 0.0 0.035"/>
    </inertial>
    <collision name="arm_1_link_4_collision">
      <geometry>
        <mesh filename="package://repair_urdf/meshes/base_meshes/link_4.stl" scale="0.001 0.001 0.001"/>
      </geometry>
      <material name="dark"/>
    </collision>
    <visual name="arm_1_link_4_visual">
      <geometry>
        <mesh filename="package://repair_urdf/meshes/base_meshes/link_4.stl" scale="0.001 0.001 0.001"/>
      </geometry>
      <material name="dark"/>
    </visual>
  </link>
  <joint name="arm_1_joint_5" type="revolute">
    <origin rpy="-1.57079632679 0 -1.57079632679" xyz="0.005 0 0"/>
    <parent link="arm_1_link_4"/>
    <child link="arm_1_link_5"/>
    <axis xyz="0 0 1"/>
    <limit effort="200.0" lower="-2.6179938779916667" upper="2.6179938779916667" velocity="10.0"/>
  </joint>
  <link name="arm_1_link_5">
    <inertial>
      <mass value="2.8"/>
      <inertia ixx="0.032" ixy="0.0" ixz="0.0017" iyy="0.033999999999999996" iyz="0.0" izz="0.028999999999999998"/>
      <origin xyz="-0.005 0.0 0.2"/>
    </inertial>
    <collision name="arm_1_link_5_collision">
      <origin rpy="0 0 0" xyz="0 0 0"/>
      <geometry>
        <mesh filename="package://repair_urdf/meshes/base_meshes/link_5.stl" scale="0.001 0.001 0.001"/>
      </geometry>
      <material name="dark"/>
    </collision>
    <visual name="arm_1_link_5_visual">
      <origin rpy="0 0 0" xyz="0 0 0"/>
      <geometry>
        <mesh filename="package://repair_urdf/meshes/base_meshes/link_5.stl" scale="0.001 0.001 0.001"/>
      </geometry>
      <material name="dark"/>
    </visual>
  </link>
  <joint name="arm_1_joint_6" type="revolute">
    <origin rpy="0 -1.57079632679 0" xyz="0 0.0 0.321 "/>
    <axis xyz="0 0 1"/>
    <parent link="arm_1_link_5"/>
    <child link="dummy_sliding_wrist1_link"/>
    <limit effort="200.0" lower="-2.6179938779916667" upper="2.6179938779916667" velocity="10.0"/>
  </joint>
  <link name="dummy_sliding_wrist1_link">
    
    </link>
  <joint name="dummy_sliding_wrist1_joint" type="prismatic">
    <origin rpy="0 0 0" xyz="0.0 0.0 0.0"/>
    <parent link="dummy_sliding_wrist1_link"/>
    <child link="arm_1_link_6"/>
    <axis xyz="0 0 -1"/>
    <limit effort="1000.0" lower="0" upper="0.1" velocity="20.0"/>
  </joint>
  <link name="arm_1_link_6">
    <inertial>
      <mass value="1.8"/>
      <inertia ixx="0.0017" ixy="0.0" ixz="0.0" iyy="0.0025" iyz="9.999999999999999e-05" izz="0.0026999999999999997"/>
      <origin xyz="0.0 0.0 0.0"/>
    </inertial>
    <collision name="arm_1_link_6_collision">
      <origin rpy="0 0 0" xyz="0 0 0"/>
      <geometry>
        <mesh filename="package://repair_urdf/meshes/base_meshes/link_6.stl" scale="0.001 0.001 0.001"/>
      </geometry>
      <material name="dark"/>
    </collision>
    <visual name="arm_1_link_6_visual">
      <origin rpy="0 0 0" xyz="0 0 0"/>
      <geometry>
        <mesh filename="package://repair_urdf/meshes/base_meshes/link_6.stl" scale="0.001 0.001 0.001"/>
      </geometry>
      <material name="dark"/>
    </visual>
  </link>
  <joint name="arm_1_joint_7" type="revolute">
    <origin rpy="1.57079632679 0 1.57079632679" xyz="0.18 0 0"/>
    <parent link="arm_1_link_6"/>
    <child link="arm_1_link_7"/>
    <axis xyz="0 0 1"/>
    <limit effort="200.0" lower="-2.6179938779916667" upper="2.6179938779916667" velocity="10.0"/>
  </joint>
  <link name="arm_1_link_7">
    <inertial>
      <mass value="1.5"/>
      <inertia ixx="0.024999999999999998" ixy="0.0" ixz="0.0" iyy="0.024999999999999998" iyz="9.999999999999999e-05" izz="0.023"/>
      <origin xyz="0.0 0.0 0.0"/>
    </inertial>
  </link>
  <joint name="arm_1_tcp_joint" type="fixed">
    <origin rpy="0 -2.3561944901874483 -1.57079632679" xyz="0 -0.014142135623730949 0.02414213562373095"/>
    <parent link="arm_1_link_7"/>
    <child link="arm_1_tcp"/>
  </joint>
  <link name="arm_1_tcp">
    <visual name="arm_1_tcp_visual">
      <origin rpy="0 0 0" xyz="0 0 0.02"/>
      <geometry>
        <mesh filename="package://repair_urdf/meshes/link_7_sh.stl" scale="0.001 0.001 0.001"/>
      </geometry>
      <material name="dark"/>
    </visual>
  </link>
  <joint name="arm_2_link_1_coll_joint" type="fixed">
    <origin rpy="0 0 0" xyz="0.0 0.0 0.0"/>
    <parent link="arm_2_link_1"/>
    <child link="arm_2_link1_coll"/>
  </joint>
  <link name="arm_2_link1_coll">
    <visual name="arm_2_link1_coll_visual">
      <origin rpy="0 0 0" xyz="0 0 0"/>
      <geometry>
        <sphere radius="0.07"/>
      </geometry>
      <material name="darkred"/>
    </visual>
  </link>
  <joint name="arm_2_link_2_coll_joint" type="fixed">
    <origin rpy="0 0 0" xyz="0.0 0 0.03"/>
    <parent link="arm_2_link_2"/>
    <child link="arm_2_link2_coll"/>
  </joint>
  <link name="arm_2_link2_coll">
    <visual name="arm_2_link2_coll_visual">
      <origin rpy="0 0 0" xyz="0 0 0"/>
      <geometry>
        <sphere radius="0.053"/>
      </geometry>
      <material name="darkred"/>
    </visual>
  </link>
  <joint name="arm_2_link_3_coll_joint" type="fixed">
    <origin rpy="0 0 0" xyz="0.0 0.0 0.22"/>
    <parent link="arm_2_link_3"/>
    <child link="arm_2_link3_coll"/>
  </joint>
  <link name="arm_2_link3_coll">
    <visual name="arm_2_link3_coll_visual">
      <origin rpy="0 0 0" xyz="0 0 0"/>
      <geometry>
        <sphere radius="0.08"/>
      </geometry>
      <material name="darkred"/>
    </visual>
  </link>
  <joint name="arm_2_link_4_coll_joint" type="fixed">
    <origin rpy="0 0 0" xyz="0.1 0.0 0.0"/>
    <parent link="arm_2_link_4"/>
    <child link="arm_2_link4_coll"/>
  </joint>
  <link name="arm_2_link4_coll">
    <visual name="arm_2_link4_coll_visual">
      <origin rpy="0 0 0" xyz="0 0 0"/>
      <geometry>
        <sphere radius="0.08"/>
      </geometry>
      <material name="darkred"/>
    </visual>
  </link>
  <joint name="arm_2_link_5_coll_joint" type="prismatic">
    <origin rpy="0 0 0" xyz="-0.1 0.0 0.321"/>
    <parent link="arm_2_link_5"/>
    <child link="arm_2_link5_coll"/>
    <limit effort="200.0" lower="0" upper="0.1" velocity="10.0"/>
    <axis xyz="1 0 0"/>
  </joint>
  <link name="arm_2_link5_coll">
    <visual name="arm_2_link5_coll_visual">
      <geometry>
        <sphere radius="0.06"/>
      </geometry>
      <material name="darkred"/>
    </visual>
  </link>
  <joint name="arm_2_link_6_coll_joint" type="fixed">
    <origin rpy="0 0 0" xyz="0.0 0.0 0.0"/>
    <parent link="arm_2_link_6"/>
    <child link="arm_2_link6_coll"/>
  </joint>
  <link name="arm_2_link6_coll">
    <visual name="arm_2_link6_coll_visual">
      <geometry>
        <sphere radius="0.07"/>
      </geometry>
      <material name="darkred"/>
    </visual>
  </link>
  <joint name="arm_2_link7_coll_joint" type="fixed">
    <origin rpy="0 0 0" xyz="0.0 0.0 -0.06"/>
    <parent link="arm_2_link_7"/>
    <child link="arm_2_link7_coll"/>
  </joint>
  <link name="arm_2_link7_coll">
    <visual name="arm_2_link7_coll_visual">
      <geometry>
        <sphere radius="0.05"/>
      </geometry>
      <material name="darkred"/>
    </visual>
  </link>
  <!-- id: 1 for right arm, everything else is considered left arm -->
  <!-- base_link: name of base link a the single arm -->
  <!-- is_sliding_wrist: whether to add a sliding joint along the axis of wrist's second d.o.f.
    (true -> yes), everything else -> no -->
  <joint name="arm_2_joint_1" type="revolute">
    <origin rpy="-1.57079632679 0 0" xyz="0 0 0"/>
    <parent link="l_arm_mount_frame"/>
    <child link="arm_2_link_1"/>
    <axis xyz="0 0 1"/>
    <limit effort="200.0" lower="-2.6179938779916667" upper="2.6179938779916667" velocity="10.0"/>
  </joint>
  <link name="arm_2_link_1">
    <inertial>
      <mass value="2"/>
      <inertia ixx="0.0015" ixy="-9.999999999999999e-05" ixz="0.0" iyy="0.0026999999999999997" iyz="9.999999999999999e-05" izz="0.0028"/>
      <origin xyz="0 0 -0.01"/>
    </inertial>
    <collision name="arm_2_link_1_collision">
      <geometry>
        <mesh filename="package://repair_urdf/meshes/base_meshes/link_1_mirror.stl" scale="0.001 0.001 0.001"/>
      </geometry>
      <material name="dark"/>
    </collision>
    <visual name="arm_2_link_1_visual">
      <geometry>
        <mesh filename="package://repair_urdf/meshes/base_meshes/link_1_mirror.stl" scale="0.001 0.001 0.001"/>
      </geometry>
      <material name="dark"/>
    </visual>
  </link>
  <joint name="arm_2_joint_2" type="revolute">
    <origin rpy="0 -1.57079632679 -3.14159265359" xyz="0.0385 0.023 0"/>
    <parent link="arm_2_link_1"/>
    <child link="arm_2_link_2"/>
    <axis xyz="0 0 1"/>
    <limit effort="200.0" lower="-1.3962634015955555" upper="2.1816615649930555" velocity="10.0"/>
  </joint>
  <link name="arm_2_link_2">
    <inertial>
      <mass value="0.4"/>
      <inertia ixx="0.00067" ixy="0.0" ixz="0.00017999999999999998" iyy="0.0009699999999999999" iyz="0.0" izz="0.001"/>
      <origin xyz="0.04 0.0 0.035"/>
    </inertial>
    <collision name="arm_2_link_2_collision">
      <geometry>
        <mesh filename="package://repair_urdf/meshes/base_meshes/link_2.stl" scale="0.001 0.001 0.001"/>
      </geometry>
      <material name="dark"/>
    </collision>
    <visual name="arm_2_link_2_visual">
      <geometry>
        <mesh filename="package://repair_urdf/meshes/base_meshes/link_2.stl" scale="0.001 0.001 0.001"/>
      </geometry>
      <material name="dark"/>
    </visual>
  </link>
  <joint name="arm_2_joint_3" type="revolute">
    <origin rpy="0 -1.57079632679 -3.14159265359" xyz="0.005 0 0"/>
    <parent link="arm_2_link_2"/>
    <child link="arm_2_link_3"/>
    <axis xyz="0 0 1"/>
    <limit effort="200.0" lower="-2.6179938779916667" upper="2.6179938779916667" velocity="10.0"/>
  </joint>
  <link name="arm_2_link_3">
    <inertial>
      <mass value="3.3"/>
      <inertia ixx="0.024999999999999998" ixy="0.0" ixz="0.0" iyy="0.026" iyz="0.0" izz="0.022"/>
      <origin xyz="0.0 -0.025 0.23"/>
    </inertial>
    <collision name="arm_2_link_3_collision">
      <geometry>
        <mesh filename="package://repair_urdf/meshes/base_meshes/link_3.stl" scale="0.001 0.001 0.001"/>
      </geometry>
      <material name="dark"/>
    </collision>
    <visual name="arm_2_link_3_visual">
      <geometry>
        <mesh filename="package://repair_urdf/meshes/base_meshes/link_3.stl" scale="0.001 0.001 0.001"/>
      </geometry>
      <material name="dark"/>
    </visual>
  </link>
  <joint name="arm_2_joint_4" type="revolute">
    <origin rpy="0 -1.57079632679 -3.14159265359" xyz="0 0.0225 0.36014999999999997"/>
    <parent link="arm_2_link_3"/>
    <child link="arm_2_link_4"/>
    <axis xyz="0 0 1"/>
    <limit effort="200.0" lower="-2.6179938779916667" upper="2.0943951023933334" velocity="10.0"/>
  </joint>
  <link name="arm_2_link_4">
    <inertial>
      <mass value="0.4"/>
      <inertia ixx="0.00067" ixy="0.0" ixz="0.00017999999999999998" iyy="0.0009699999999999999" iyz="0.0" izz="0.001"/>
      <origin xyz="0.04 0.0 0.035"/>
    </inertial>
    <collision name="arm_2_link_4_collision">
      <geometry>
        <mesh filename="package://repair_urdf/meshes/base_meshes/link_4.stl" scale="0.001 0.001 0.001"/>
      </geometry>
      <material name="dark"/>
    </collision>
    <visual name="arm_2_link_4_visual">
      <geometry>
        <mesh filename="package://repair_urdf/meshes/base_meshes/link_4.stl" scale="0.001 0.001 0.001"/>
      </geometry>
      <material name="dark"/>
    </visual>
  </link>
  <joint name="arm_2_joint_5" type="revolute">
    <origin rpy="-1.57079632679 0 -1.57079632679" xyz="0.005 0 0"/>
    <parent link="arm_2_link_4"/>
    <child link="arm_2_link_5"/>
    <axis xyz="0 0 1"/>
    <limit effort="200.0" lower="-2.6179938779916667" upper="2.6179938779916667" velocity="10.0"/>
  </joint>
  <link name="arm_2_link_5">
    <inertial>
      <mass value="2.8"/>
      <inertia ixx="0.032" ixy="0.0" ixz="0.0017" iyy="0.033999999999999996" iyz="0.0" izz="0.028999999999999998"/>
      <origin xyz="-0.005 0.0 0.2"/>
    </inertial>
    <collision name="arm_2_link_5_collision">
      <origin rpy="0 0 0" xyz="0 0 0"/>
      <geometry>
        <mesh filename="package://repair_urdf/meshes/base_meshes/link_5.stl" scale="0.001 0.001 0.001"/>
      </geometry>
      <material name="dark"/>
    </collision>
    <visual name="arm_2_link_5_visual">
      <origin rpy="0 0 0" xyz="0 0 0"/>
      <geometry>
        <mesh filename="package://repair_urdf/meshes/base_meshes/link_5.stl" scale="0.001 0.001 0.001"/>
      </geometry>
      <material name="dark"/>
    </visual>
  </link>
  <joint name="arm_2_joint_6" type="revolute">
    <origin rpy="0 -1.57079632679 0" xyz="0 0.0 0.321 "/>
    <axis xyz="0 0 1"/>
    <parent link="arm_2_link_5"/>
    <child link="dummy_sliding_wrist2_link"/>
    <limit effort="200.0" lower="-2.6179938779916667" upper="2.6179938779916667" velocity="10.0"/>
  </joint>
  <link name="dummy_sliding_wrist2_link">
    
    </link>
  <joint name="dummy_sliding_wrist2_joint" type="prismatic">
    <origin rpy="0 0 0" xyz="0.0 0.0 0.0"/>
    <parent link="dummy_sliding_wrist2_link"/>
    <child link="arm_2_link_6"/>
    <axis xyz="0 0 -1"/>
    <limit effort="1000.0" lower="0" upper="0.1" velocity="20.0"/>
  </joint>
  <link name="arm_2_link_6">
    <inertial>
      <mass value="1.8"/>
      <inertia ixx="0.0017" ixy="0.0" ixz="0.0" iyy="0.0025" iyz="9.999999999999999e-05" izz="0.0026999999999999997"/>
      <origin xyz="0.0 0.0 0.0"/>
    </inertial>
    <collision name="arm_2_link_6_collision">
      <origin rpy="0 0 0" xyz="0 0 0"/>
      <geometry>
        <mesh filename="package://repair_urdf/meshes/base_meshes/link_6.stl" scale="0.001 0.001 0.001"/>
      </geometry>
      <material name="dark"/>
    </collision>
    <visual name="arm_2_link_6_visual">
      <origin rpy="0 0 0" xyz="0 0 0"/>
      <geometry>
        <mesh filename="package://repair_urdf/meshes/base_meshes/link_6.stl" scale="0.001 0.001 0.001"/>
      </geometry>
      <material name="dark"/>
    </visual>
  </link>
  <joint name="arm_2_joint_7" type="revolute">
    <origin rpy="-1.57079632679 3.14159265359 -1.57079632679" xyz="0.18 0 0"/>
    <!-- <origin xyz="${180.000 * mmTom} 0 0" rpy="${-PI_2} 0 ${-PI_2}"/> -->
    <parent link="arm_2_link_6"/>
    <child link="arm_2_link_7"/>
    <axis xyz="0 0 1"/>
    <limit effort="200.0" lower="-2.6179938779916667" upper="2.6179938779916667" velocity="10.0"/>
  </joint>
  <link name="arm_2_link_7">
    <inertial>
      <mass value="1.5"/>
      <inertia ixx="0.024999999999999998" ixy="0.0" ixz="0.0" iyy="0.024999999999999998" iyz="9.999999999999999e-05" izz="0.023"/>
      <origin xyz="0.0 0.0 0.0"/>
    </inertial>
  </link>
  <joint name="arm_2_tcp_joint" type="fixed">
    <origin rpy="0 -2.3561944901874483 -1.57079632679" xyz="0 -0.014142135623730949 0.02414213562373095"/>
    <parent link="arm_2_link_7"/>
    <child link="arm_2_tcp"/>
  </joint>
  <link name="arm_2_tcp">
    <visual name="arm_2_tcp_visual">
      <origin rpy="0 0 0" xyz="0 0 0.02"/>
      <geometry>
        <mesh filename="package://repair_urdf/meshes/link_7_rh.stl" scale="0.001 0.001 0.001"/>
      </geometry>
      <material name="dark"/>
    </visual>
  </link>
  <gazebo reference="arm_1_link_1">
    <material>Gazebo/BlackTransparent   </material>
  </gazebo>
  <gazebo reference="arm_1_link_2">
    <material>Gazebo/GreenTransparent    </material>
  </gazebo>
  <gazebo reference="arm_1_link_3">
    <material>Gazebo/BlackTransparent   </material>
  </gazebo>
  <gazebo reference="arm_1_link_4">
    <material>Gazebo/GreenTransparent    </material>
  </gazebo>
  <gazebo reference="arm_1_link_5">
    <material>Gazebo/BlackTransparent  </material>
  </gazebo>
  <gazebo reference="arm_1_link_6">
    <material>Gazebo/GreenTransparent    </material>
  </gazebo>
  <gazebo reference="arm_1_link_7">
    <material>Gazebo/BlackTransparent  </material>
  </gazebo>
  <gazebo reference="arm_1_tcp">
    <material>Gazebo/GreyTransparent    </material>
  </gazebo>
  <gazebo reference="arm_2_link_1">
    <material>Gazebo/BlackTransparent   </material>
  </gazebo>
  <gazebo reference="arm_2_link_2">
    <material>Gazebo/GreenTransparent    </material>
  </gazebo>
  <gazebo reference="arm_2_link_3">
    <material>Gazebo/BlackTransparent   </material>
  </gazebo>
  <gazebo reference="arm_2_link_4">
    <material>Gazebo/GreenTransparent    </material>
  </gazebo>
  <gazebo reference="arm_2_link_5">
    <material>Gazebo/BlackTransparent  </material>
  </gazebo>
  <gazebo reference="arm_2_link_6">
    <material>Gazebo/GreenTransparent    </material>
  </gazebo>
  <gazebo reference="arm_2_link_7">
    <material>Gazebo/BlackTransparent  </material>
  </gazebo>
  <gazebo reference="arm_2_tcp">
    <material>Gazebo/GreyTransparent    </material>
  </gazebo>
  <gazebo reference="base_link">
    <material>Gazebo/GreenTransparent   </material>
  </gazebo>
</robot>
