<?xml version="1.0" ?>
<!-- =================================================================================== -->
<!-- |    This document was autogenerated by xacro from /home/andreap/hhcm_ws/src/iit-repair-ros-pkg/repair_urdf/urdf/repair_full.urdf.xacro | -->
<!-- |    EDITING THIS FILE BY HAND IS NOT RECOMMENDED                                 | -->
<!-- =================================================================================== -->
<robot name="table">
  <!-- color -->
  <material name="darkblue">
    <color rgba="0.0 0.3 0.9 1"/>
  </material>
  <material name="dark">
    <color rgba="0.6 0.6 0.6 1"/>
  </material>
  <material name="wood">
    <color rgba="0.522 0.369 0.259 0.8"/>
  </material>
  <material name="silver_gray">
    <color rgba="0.8 0.8 0.8 0.8"/>
  </material>
  <link name="world">
  </link>
  <joint name="world_joint" type="fixed">
    <parent link="world"/>
    <origin rpy="0 0 0" xyz="0 0 0"/>
    <child link="table_top_link"/>
  </joint>
  <link name="table_top_link">
    <inertial>
      <mass value="1.0"/>
      <origin xyz="0.98 0.0 0.475"/>
      <inertia ixx="1" ixy="0" ixz="0" iyy="1" iyz="0" izz="1"/>
    </inertial>
    <visual>
      <origin xyz="0.98 0.0 0.475"/>
      <geometry>
        <box size="1.5 2.5 0.05"/>
      </geometry>
      <material name="wood"/>
    </visual>
    <collision>
      <origin xyz="0.98 0.0 0.475"/>
      <geometry>
        <box size="1.5 2.5 0.05"/>
      </geometry>
    </collision>
  </link>
  <joint name="leg1_joint" type="fixed">
    <parent link="table_top_link"/>
    <origin rpy="0 0 0" xyz="1.73 1.25 0.5"/>
    <child link="leg1_link"/>
  </joint>
  <link name="leg1_link">
    <inertial>
      <mass value="1.0"/>
      <origin xyz="0 0 -0.25"/>
      <inertia ixx="0.1" ixy="0" ixz="0" iyy="0.1" iyz="0" izz="0.01"/>
    </inertial>
    <visual>
      <origin rpy="0 0 0" xyz="0.0 0.0 -0.25"/>
      <geometry>
        <cylinder length="0.5" radius="0.02"/>
      </geometry>
      <material name="silver_gray"/>
    </visual>
    <collision>
      <origin rpy="0.0 0.0 0.0" xyz="0.0 0.0 -0.25"/>
      <geometry>
        <cylinder length="0.5" radius="0.02"/>
      </geometry>
    </collision>
  </link>
  <joint name="vbar1_joint" type="fixed">
    <parent link="leg1_link"/>
    <origin rpy="0 0 0" xyz="0 0 0.5"/>
    <child link="vbar1_link"/>
  </joint>
  <link name="vbar1_link">
    <inertial>
      <mass value="1.0"/>
      <origin xyz="0 0 0"/>
      <inertia ixx="0.1" ixy="0" ixz="0" iyy="0.1" iyz="0" izz="0.01"/>
    </inertial>
    <visual>
      <origin rpy="0 0 0" xyz="0.0 0.0 0"/>
      <geometry>
        <cylinder length="1.0" radius="0.02"/>
      </geometry>
      <material name="silver_gray"/>
    </visual>
    <collision>
      <origin rpy="0.0 0.0 0.0" xyz="0.0 0.0 0"/>
      <geometry>
        <cylinder length="1.0" radius="0.02"/>
      </geometry>
    </collision>
  </link>
  <joint name="leg2_joint" type="fixed">
    <parent link="table_top_link"/>
    <origin rpy="0 0 0" xyz="0.22999999999999998 1.25 0.5"/>
    <child link="leg2_link"/>
  </joint>
  <link name="leg2_link">
    <inertial>
      <mass value="1.0"/>
      <origin xyz="0 0 -0.25"/>
      <inertia ixx="0.1" ixy="0" ixz="0" iyy="0.1" iyz="0" izz="0.01"/>
    </inertial>
    <visual>
      <origin rpy="0 0 0" xyz="0.0 0.0 -0.25"/>
      <geometry>
        <cylinder length="0.5" radius="0.02"/>
      </geometry>
      <material name="silver_gray"/>
    </visual>
    <collision>
      <origin rpy="0.0 0.0 0.0" xyz="0.0 0.0 -0.25"/>
      <geometry>
        <cylinder length="0.5" radius="0.02"/>
      </geometry>
    </collision>
  </link>
  <joint name="vbar2_joint" type="fixed">
    <parent link="leg2_link"/>
    <origin rpy="0 0 0" xyz="0 0 0.5"/>
    <child link="vbar2_link"/>
  </joint>
  <link name="vbar2_link">
    <inertial>
      <mass value="1.0"/>
      <origin xyz="0 0 0"/>
      <inertia ixx="0.1" ixy="0" ixz="0" iyy="0.1" iyz="0" izz="0.01"/>
    </inertial>
    <visual>
      <origin rpy="0 0 0" xyz="0.0 0.0 0"/>
      <geometry>
        <cylinder length="1.0" radius="0.02"/>
      </geometry>
      <material name="silver_gray"/>
    </visual>
    <collision>
      <origin rpy="0.0 0.0 0.0" xyz="0.0 0.0 0"/>
      <geometry>
        <cylinder length="1.0" radius="0.02"/>
      </geometry>
    </collision>
  </link>
  <joint name="leg3_joint" type="fixed">
    <parent link="table_top_link"/>
    <origin rpy="0 0 0" xyz="1.73 -1.25 0.5"/>
    <child link="leg3_link"/>
  </joint>
  <link name="leg3_link">
    <inertial>
      <mass value="1.0"/>
      <origin xyz="0 0 -0.25"/>
      <inertia ixx="0.1" ixy="0" ixz="0" iyy="0.1" iyz="0" izz="0.01"/>
    </inertial>
    <visual>
      <origin rpy="0 0 0" xyz="0.0 0.0 -0.25"/>
      <geometry>
        <cylinder length="0.5" radius="0.02"/>
      </geometry>
      <material name="silver_gray"/>
    </visual>
    <collision>
      <origin rpy="0.0 0.0 0.0" xyz="0.0 0.0 -0.25"/>
      <geometry>
        <cylinder length="0.5" radius="0.02"/>
      </geometry>
    </collision>
  </link>
  <joint name="vbar3_joint" type="fixed">
    <parent link="leg3_link"/>
    <origin rpy="0 0 0" xyz="0 0 0.5"/>
    <child link="vbar3_link"/>
  </joint>
  <link name="vbar3_link">
    <inertial>
      <mass value="1.0"/>
      <origin xyz="0 0 0"/>
      <inertia ixx="0.1" ixy="0" ixz="0" iyy="0.1" iyz="0" izz="0.01"/>
    </inertial>
    <visual>
      <origin rpy="0 0 0" xyz="0.0 0.0 0"/>
      <geometry>
        <cylinder length="1.0" radius="0.02"/>
      </geometry>
      <material name="silver_gray"/>
    </visual>
    <collision>
      <origin rpy="0.0 0.0 0.0" xyz="0.0 0.0 0"/>
      <geometry>
        <cylinder length="1.0" radius="0.02"/>
      </geometry>
    </collision>
  </link>
  <joint name="leg4_joint" type="fixed">
    <parent link="table_top_link"/>
    <origin rpy="0 0 0" xyz="0.22999999999999998 -1.25 0.5"/>
    <child link="leg4_link"/>
  </joint>
  <link name="leg4_link">
    <inertial>
      <mass value="1.0"/>
      <origin xyz="0 0 -0.25"/>
      <inertia ixx="0.1" ixy="0" ixz="0" iyy="0.1" iyz="0" izz="0.01"/>
    </inertial>
    <visual>
      <origin rpy="0 0 0" xyz="0.0 0.0 -0.25"/>
      <geometry>
        <cylinder length="0.5" radius="0.02"/>
      </geometry>
      <material name="silver_gray"/>
    </visual>
    <collision>
      <origin rpy="0.0 0.0 0.0" xyz="0.0 0.0 -0.25"/>
      <geometry>
        <cylinder length="0.5" radius="0.02"/>
      </geometry>
    </collision>
  </link>
  <joint name="vbar4_joint" type="fixed">
    <parent link="leg4_link"/>
    <origin rpy="0 0 0" xyz="0 0 0.5"/>
    <child link="vbar4_link"/>
  </joint>
  <link name="vbar4_link">
    <inertial>
      <mass value="1.0"/>
      <origin xyz="0 0 0"/>
      <inertia ixx="0.1" ixy="0" ixz="0" iyy="0.1" iyz="0" izz="0.01"/>
    </inertial>
    <visual>
      <origin rpy="0 0 0" xyz="0.0 0.0 0"/>
      <geometry>
        <cylinder length="1.0" radius="0.02"/>
      </geometry>
      <material name="silver_gray"/>
    </visual>
    <collision>
      <origin rpy="0.0 0.0 0.0" xyz="0.0 0.0 0"/>
      <geometry>
        <cylinder length="1.0" radius="0.02"/>
      </geometry>
    </collision>
  </link>
  <joint name="obar1_joint" type="fixed">
    <parent link="vbar1_link"/>
    <origin rpy="0 -1.57079632679 0" xyz="-0.75 0 0.5"/>
    <child link="obar1_link"/>
  </joint>
  <link name="obar1_link">
    <inertial>
      <mass value="1.0"/>
      <origin xyz="0 0 0"/>
      <inertia ixx="0.1" ixy="0" ixz="0" iyy="0.1" iyz="0" izz="0.01"/>
    </inertial>
    <visual>
      <origin rpy="0 0 0" xyz="0.0 0.0 0"/>
      <geometry>
        <cylinder length="1.5" radius="0.02"/>
      </geometry>
      <material name="silver_gray"/>
    </visual>
    <collision>
      <origin rpy="0.0 0.0 0.0" xyz="0.0 0.0 0"/>
      <geometry>
        <cylinder length="1.5" radius="0.02"/>
      </geometry>
    </collision>
  </link>
  <joint name="obar2_joint" type="fixed">
    <parent link="vbar3_link"/>
    <origin rpy="0 -1.57079632679 0" xyz="-0.75 0 0.5"/>
    <child link="obar2_link"/>
  </joint>
  <link name="obar2_link">
    <inertial>
      <mass value="1.0"/>
      <origin xyz="0 0 0"/>
      <inertia ixx="0.1" ixy="0" ixz="0" iyy="0.1" iyz="0" izz="0.01"/>
    </inertial>
    <visual>
      <origin rpy="0 0 0" xyz="0.0 0.0 0"/>
      <geometry>
        <cylinder length="1.5" radius="0.02"/>
      </geometry>
      <material name="silver_gray"/>
    </visual>
    <collision>
      <origin rpy="0.0 0.0 0.0" xyz="0.0 0.0 0"/>
      <geometry>
        <cylinder length="1.5" radius="0.02"/>
      </geometry>
    </collision>
  </link>
  <joint name="obar3_joint" type="fixed">
    <parent link="vbar3_link"/>
    <origin rpy="-1.57079632679 0 0" xyz="0 1.25 0.5"/>
    <child link="obar3_link"/>
  </joint>
  <link name="obar3_link">
    <inertial>
      <mass value="1.0"/>
      <origin xyz="0 0 0"/>
      <inertia ixx="0.1" ixy="0" ixz="0" iyy="0.1" iyz="0" izz="0.01"/>
    </inertial>
    <visual>
      <origin rpy="0 0 0" xyz="0.0 0.0 0"/>
      <geometry>
        <cylinder length="2.5" radius="0.02"/>
      </geometry>
      <material name="silver_gray"/>
    </visual>
    <collision>
      <origin rpy="0.0 0.0 0.0" xyz="0.0 0.0 0"/>
      <geometry>
        <cylinder length="2.5" radius="0.02"/>
      </geometry>
    </collision>
  </link>
  <joint name="obar4_joint" type="fixed">
    <parent link="vbar4_link"/>
    <origin rpy="-1.57079632679 0 0" xyz="0 1.25 0.5"/>
    <child link="obar4_link"/>
  </joint>
  <link name="obar4_link">
    <inertial>
      <mass value="1.0"/>
      <origin xyz="0 0 0"/>
      <inertia ixx="0.1" ixy="0" ixz="0" iyy="0.1" iyz="0" izz="0.01"/>
    </inertial>
    <visual>
      <origin rpy="0 0 0" xyz="0.0 0.0 0"/>
      <geometry>
        <cylinder length="2.5" radius="0.02"/>
      </geometry>
      <material name="silver_gray"/>
    </visual>
    <collision>
      <origin rpy="0.0 0.0 0.0" xyz="0.0 0.0 0"/>
      <geometry>
        <cylinder length="2.5" radius="0.02"/>
      </geometry>
    </collision>
  </link>
  <joint name="sliding_guide_joint" type="fixed">
    <parent link="obar2_link"/>
    <origin rpy="-1.57079632679 0 0" xyz="0 1.25 0"/>
    <child link="sliding_guide_link"/>
  </joint>
  <link name="sliding_guide_link">
    <inertial>
      <mass value="1.0"/>
      <origin xyz="0 0 0"/>
      <inertia ixx="0.1" ixy="0" ixz="0" iyy="0.1" iyz="0" izz="0.01"/>
    </inertial>
    <visual>
      <origin rpy="0 0 0" xyz="0.0 0.0 0"/>
      <geometry>
        <box size="0.001 0.2 2.5"/>
      </geometry>
      <material name="silver_gray"/>
    </visual>
    <collision>
      <origin rpy="0.0 0.0 0.0" xyz="0.0 0.0 0"/>
      <geometry>
        <cylinder length="2.5" radius="0.02"/>
      </geometry>
    </collision>
  </link>
  <joint name="working_surface_joint" type="fixed">
    <parent link="sliding_guide_link"/>
    <origin rpy="0.0 -1.57079632679 3.14159265359" xyz="-1.0 0 0"/>
    <child link="working_surface_link"/>
  </joint>
  <link name="working_surface_link">
  </link>
  <joint name="x_joint" type="prismatic">
    <origin rpy="0.0 0.0 0.0" xyz="0.0 0.0 0.0"/>
    <parent link="working_surface_link"/>
    <child link="dummy_link"/>
    <axis xyz="1 0 0"/>
    <limit effort="1000.0" lower="-1.15" upper="1.15" velocity="20.0"/>
  </joint>
  <link name="dummy_link">
</link>
  <joint name="z_joint" type="prismatic">
    <origin rpy="0.0 0.0 0.0" xyz="0.0 0.0 0.0"/>
    <parent link="dummy_link"/>
    <child link="base_link"/>
    <axis xyz="0 0 1"/>
    <limit effort="1000.0" lower="0.1" upper="0.9" velocity="20.0"/>
  </joint>
  <!-- RePAIR assembly (two arms) -->
  <link name="base_link">
</link>
  <joint name="r_arm_mount_joint" type="prismatic">
    <origin rpy="-1.57079632679 0 3.14159265359" xyz="0.0 0.0 0.0"/>
    <parent link="base_link"/>
    <child link="dummy_r"/>
    <axis xyz="0 0 1"/>
    <limit effort="1000.0" lower="0.25" upper="0.6" velocity="20.0"/>
  </joint>
  <link name="dummy_r">
</link>
  <joint name="roll_r" type="revolute">
    <origin rpy="0.0 0.0 0.0" xyz="0.0 0.0 0.0"/>
    <parent link="dummy_r"/>
    <child link="r_arm_mount_frame"/>
    <axis xyz="-1 0 0"/>
    <limit effort="0.0" lower="-0.7853981633975" upper="0.7853981633975" velocity="0.0"/>
  </joint>
  <link name="r_arm_mount_frame">
</link>
  <joint name="arm_1_joint_1" type="revolute">
    <origin rpy="0 0 0" xyz="0 0 0"/>
    <parent link="r_arm_mount_frame"/>
    <child link="arm_1_link_1"/>
    <axis xyz="0 0 1"/>
    <limit effort="200.0" lower="-2.6179938779916667" upper="2.6179938779916667" velocity="10.0"/>
  </joint>
  <joint name="arm_1_joint_2" type="revolute">
    <origin rpy="0 -1.57079632679 3.14159265359" xyz="0.007 0 0"/>
    <parent link="arm_1_link_1"/>
    <child link="arm_1_link_2"/>
    <axis xyz="0 0 1"/>
    <limit effort="200.0" lower="-1.570796326795" upper="1.570796326795" velocity="10.0"/>
  </joint>
  <joint name="arm_1_joint_3" type="revolute">
    <origin rpy="0 -1.57079632679 3.14159265359" xyz="0 0 0"/>
    <parent link="arm_1_link_2"/>
    <child link="arm_1_link_3"/>
    <axis xyz="0 0 1"/>
    <limit effort="200.0" lower="-2.6179938779916667" upper="2.6179938779916667" velocity="10.0"/>
  </joint>
  <joint name="arm_1_joint_4" type="revolute">
    <origin rpy="0 -1.57079632679 3.14159265359" xyz="0 0.0225 0.36014999999999997"/>
    <parent link="arm_1_link_3"/>
    <child link="arm_1_link_4"/>
    <axis xyz="0 0 1"/>
    <limit effort="200.0" lower="-2.6179938779916667" upper="0.8726646259972222" velocity="10.0"/>
  </joint>
  <joint name="arm_1_joint_5" type="revolute">
    <origin rpy="0 -1.57079632679 3.14159265359" xyz="0 0 0"/>
    <parent link="arm_1_link_4"/>
    <child link="arm_1_link_5"/>
    <axis xyz="0 0 1"/>
    <limit effort="200.0" lower="-2.6179938779916667" upper="2.6179938779916667" velocity="10.0"/>
  </joint>
  <joint name="arm_1_joint_6" type="revolute">
    <origin rpy="0 -1.57079632679 3.14159265359" xyz="0 0 0.321"/>
    <parent link="arm_1_link_5"/>
    <child link="arm_1_link_6"/>
    <axis xyz="0 0 1"/>
    <limit effort="200.0" lower="-2.6179938779916667" upper="2.6179938779916667" velocity="10.0"/>
  </joint>
  <joint name="arm_1_joint_7" type="revolute">
    <origin rpy="0 -1.57079632679 3.14159265359" xyz="0.18 0 0"/>
    <parent link="arm_1_link_6"/>
    <child link="arm_1_link_7"/>
    <axis xyz="0 0 1"/>
    <limit effort="200.0" lower="-2.6179938779916667" upper="2.6179938779916667" velocity="10.0"/>
  </joint>
  <joint name="arm_1_tcp_joint" type="fixed">
    <origin rpy="0 0 0" xyz="0 0 0"/>
    <parent link="arm_1_link_7"/>
    <child link="arm_1_tcp"/>
  </joint>
  <link name="arm_1_link_1">
    <inertial>
      <mass value="0.1"/>
      <inertia ixx="0.0001" ixy="0" ixz="0" iyy="0.0001" iyz="0" izz="0.0001"/>
      <origin xyz="0 0 0"/>
    </inertial>
    <collision name="arm_1_link_1_collision">
      <geometry>
        <mesh filename="package://repair_urdf/meshes/link_1.stl" scale="0.001 0.001 0.001"/>
      </geometry>
      <material name="dark"/>
    </collision>
    <visual name="arm_1_link_1_visual">
      <geometry>
        <mesh filename="package://repair_urdf/meshes/link_1.stl" scale="0.001 0.001 0.001"/>
      </geometry>
      <material name="dark"/>
    </visual>
  </link>
  <link name="arm_1_link_2">
    <inertial>
      <mass value="0.1"/>
      <inertia ixx="0.0001" ixy="0" ixz="0" iyy="0.0001" iyz="0" izz="0.0001"/>
      <origin xyz="0 0 0"/>
    </inertial>
    <collision name="arm_1_link_2_collision">
      <geometry>
        <mesh filename="package://repair_urdf/meshes/link_2.stl" scale="0.001 0.001 0.001"/>
      </geometry>
      <material name="dark"/>
    </collision>
    <visual name="arm_1_link_2_visual">
      <geometry>
        <mesh filename="package://repair_urdf/meshes/link_2.stl" scale="0.001 0.001 0.001"/>
      </geometry>
      <material name="dark"/>
    </visual>
  </link>
  <link name="arm_1_link_3">
    <inertial>
      <mass value="0.1"/>
      <inertia ixx="0.0001" ixy="0" ixz="0" iyy="0.0001" iyz="0" izz="0.0001"/>
      <origin xyz="0 0 0"/>
    </inertial>
    <collision name="arm_1_link_3_collision">
      <geometry>
        <mesh filename="package://repair_urdf/meshes/link_3.stl" scale="0.001 0.001 0.001"/>
      </geometry>
      <material name="dark"/>
    </collision>
    <visual name="arm_1_link_3_visual">
      <geometry>
        <mesh filename="package://repair_urdf/meshes/link_3.stl" scale="0.001 0.001 0.001"/>
      </geometry>
      <material name="dark"/>
    </visual>
  </link>
  <link name="arm_1_link_4">
    <inertial>
      <mass value="0.1"/>
      <inertia ixx="0.0001" ixy="0" ixz="0" iyy="0.0001" iyz="0" izz="0.0001"/>
      <origin xyz="0 0 0"/>
    </inertial>
    <collision name="arm_1_link_4_collision">
      <geometry>
        <mesh filename="package://repair_urdf/meshes/link_4.stl" scale="0.001 0.001 0.001"/>
      </geometry>
      <material name="dark"/>
    </collision>
    <visual name="arm_1_link_4_visual">
      <geometry>
        <mesh filename="package://repair_urdf/meshes/link_4.stl" scale="0.001 0.001 0.001"/>
      </geometry>
      <material name="dark"/>
    </visual>
  </link>
  <link name="arm_1_link_5">
    <inertial>
      <mass value="0.1"/>
      <inertia ixx="0.0001" ixy="0" ixz="0" iyy="0.0001" iyz="0" izz="0.0001"/>
      <origin xyz="0 0 0"/>
    </inertial>
    <collision name="arm_1_link_5_collision">
      <geometry>
        <mesh filename="package://repair_urdf/meshes/link_5.stl" scale="0.001 0.001 0.001"/>
      </geometry>
      <material name="dark"/>
    </collision>
    <visual name="arm_1_link_5_visual">
      <geometry>
        <mesh filename="package://repair_urdf/meshes/link_5.stl" scale="0.001 0.001 0.001"/>
      </geometry>
      <material name="dark"/>
    </visual>
  </link>
  <link name="arm_1_link_6">
    <inertial>
      <mass value="0.1"/>
      <inertia ixx="0.0001" ixy="0" ixz="0" iyy="0.0001" iyz="0" izz="0.0001"/>
      <origin xyz="0 0 0"/>
    </inertial>
    <collision name="arm_1_link_6_collision">
      <geometry>
        <mesh filename="package://repair_urdf/meshes/link_6.stl" scale="0.001 0.001 0.001"/>
      </geometry>
      <material name="dark"/>
    </collision>
    <visual name="arm_1_link_6_visual">
      <geometry>
        <mesh filename="package://repair_urdf/meshes/link_6.stl" scale="0.001 0.001 0.001"/>
      </geometry>
      <material name="dark"/>
    </visual>
  </link>
  <link name="arm_1_link_7">
    <inertial>
      <mass value="0.1"/>
      <inertia ixx="0.0001" ixy="0" ixz="0" iyy="0.0001" iyz="0" izz="0.0001"/>
      <origin xyz="0 0 0"/>
    </inertial>
    <collision name="arm_1_link_7_collision">
      <geometry>
        <mesh filename="package://repair_urdf/meshes/link_7.stl" scale="0.001 0.001 0.001"/>
      </geometry>
      <material name="dark"/>
    </collision>
    <visual name="arm_1_link_7_visual">
      <geometry>
        <mesh filename="package://repair_urdf/meshes/link_7.stl" scale="0.001 0.001 0.001"/>
      </geometry>
      <material name="dark"/>
    </visual>
  </link>
  <link name="arm_1_tcp"/>
  <joint name="l_arm_mount_joint" type="prismatic">
    <origin rpy="-1.57079632679 0 0" xyz="0.0 0.0 0.0"/>
    <parent link="base_link"/>
    <child link="dummy_l"/>
    <axis xyz="0 0 1"/>
    <limit effort="1000.0" lower="0.25" upper="0.6" velocity="20.0"/>
  </joint>
  <link name="dummy_l">
</link>
  <joint name="roll_l" type="revolute">
    <origin rpy="0.0 0.0 0.0" xyz="0.0 0.0 0.0"/>
    <parent link="dummy_l"/>
    <child link="l_arm_mount_frame"/>
    <axis xyz="-1 0 0"/>
    <limit effort="0.0" lower="-0.7853981633975" upper="0.7853981633975" velocity="0.0"/>
  </joint>
  <link name="l_arm_mount_frame">
</link>
  <joint name="arm_2_joint_1" type="revolute">
    <origin rpy="0 0 0" xyz="0 0 0"/>
    <parent link="l_arm_mount_frame"/>
    <child link="arm_2_link_1"/>
    <axis xyz="0 0 1"/>
    <limit effort="200.0" lower="-2.6179938779916667" upper="2.6179938779916667" velocity="10.0"/>
  </joint>
  <joint name="arm_2_joint_2" type="revolute">
    <origin rpy="0 -1.57079632679 3.14159265359" xyz="0.007 0 0"/>
    <parent link="arm_2_link_1"/>
    <child link="arm_2_link_2"/>
    <axis xyz="0 0 1"/>
    <limit effort="200.0" lower="-1.570796326795" upper="1.570796326795" velocity="10.0"/>
  </joint>
  <joint name="arm_2_joint_3" type="revolute">
    <origin rpy="0 -1.57079632679 3.14159265359" xyz="0 0 0"/>
    <parent link="arm_2_link_2"/>
    <child link="arm_2_link_3"/>
    <axis xyz="0 0 1"/>
    <limit effort="200.0" lower="-2.6179938779916667" upper="2.6179938779916667" velocity="10.0"/>
  </joint>
  <joint name="arm_2_joint_4" type="revolute">
    <origin rpy="0 -1.57079632679 3.14159265359" xyz="0 0.0225 0.36014999999999997"/>
    <parent link="arm_2_link_3"/>
    <child link="arm_2_link_4"/>
    <axis xyz="0 0 1"/>
    <limit effort="200.0" lower="-2.6179938779916667" upper="0.8726646259972222" velocity="10.0"/>
  </joint>
  <joint name="arm_2_joint_5" type="revolute">
    <origin rpy="0 -1.57079632679 3.14159265359" xyz="0 0 0"/>
    <parent link="arm_2_link_4"/>
    <child link="arm_2_link_5"/>
    <axis xyz="0 0 1"/>
    <limit effort="200.0" lower="-2.6179938779916667" upper="2.6179938779916667" velocity="10.0"/>
  </joint>
  <joint name="arm_2_joint_6" type="revolute">
    <origin rpy="0 -1.57079632679 3.14159265359" xyz="0 0 0.321"/>
    <parent link="arm_2_link_5"/>
    <child link="arm_2_link_6"/>
    <axis xyz="0 0 1"/>
    <limit effort="200.0" lower="-2.6179938779916667" upper="2.6179938779916667" velocity="10.0"/>
  </joint>
  <joint name="arm_2_joint_7" type="revolute">
    <origin rpy="0 -1.57079632679 3.14159265359" xyz="0.18 0 0"/>
    <parent link="arm_2_link_6"/>
    <child link="arm_2_link_7"/>
    <axis xyz="0 0 1"/>
    <limit effort="200.0" lower="-2.6179938779916667" upper="2.6179938779916667" velocity="10.0"/>
  </joint>
  <joint name="arm_2_tcp_joint" type="fixed">
    <origin rpy="0 0 0" xyz="0 0 0"/>
    <parent link="arm_2_link_7"/>
    <child link="arm_2_tcp"/>
  </joint>
  <link name="arm_2_link_1">
    <inertial>
      <mass value="0.1"/>
      <inertia ixx="0.0001" ixy="0" ixz="0" iyy="0.0001" iyz="0" izz="0.0001"/>
      <origin xyz="0 0 0"/>
    </inertial>
    <collision name="arm_2_link_1_collision">
      <geometry>
        <mesh filename="package://repair_urdf/meshes/link_1.stl" scale="0.001 0.001 0.001"/>
      </geometry>
      <material name="dark"/>
    </collision>
    <visual name="arm_2_link_1_visual">
      <geometry>
        <mesh filename="package://repair_urdf/meshes/link_1.stl" scale="0.001 0.001 0.001"/>
      </geometry>
      <material name="dark"/>
    </visual>
  </link>
  <link name="arm_2_link_2">
    <inertial>
      <mass value="0.1"/>
      <inertia ixx="0.0001" ixy="0" ixz="0" iyy="0.0001" iyz="0" izz="0.0001"/>
      <origin xyz="0 0 0"/>
    </inertial>
    <collision name="arm_2_link_2_collision">
      <geometry>
        <mesh filename="package://repair_urdf/meshes/link_2.stl" scale="0.001 0.001 0.001"/>
      </geometry>
      <material name="dark"/>
    </collision>
    <visual name="arm_2_link_2_visual">
      <geometry>
        <mesh filename="package://repair_urdf/meshes/link_2.stl" scale="0.001 0.001 0.001"/>
      </geometry>
      <material name="dark"/>
    </visual>
  </link>
  <link name="arm_2_link_3">
    <inertial>
      <mass value="0.1"/>
      <inertia ixx="0.0001" ixy="0" ixz="0" iyy="0.0001" iyz="0" izz="0.0001"/>
      <origin xyz="0 0 0"/>
    </inertial>
    <collision name="arm_2_link_3_collision">
      <geometry>
        <mesh filename="package://repair_urdf/meshes/link_3.stl" scale="0.001 0.001 0.001"/>
      </geometry>
      <material name="dark"/>
    </collision>
    <visual name="arm_2_link_3_visual">
      <geometry>
        <mesh filename="package://repair_urdf/meshes/link_3.stl" scale="0.001 0.001 0.001"/>
      </geometry>
      <material name="dark"/>
    </visual>
  </link>
  <link name="arm_2_link_4">
    <inertial>
      <mass value="0.1"/>
      <inertia ixx="0.0001" ixy="0" ixz="0" iyy="0.0001" iyz="0" izz="0.0001"/>
      <origin xyz="0 0 0"/>
    </inertial>
    <collision name="arm_2_link_4_collision">
      <geometry>
        <mesh filename="package://repair_urdf/meshes/link_4.stl" scale="0.001 0.001 0.001"/>
      </geometry>
      <material name="dark"/>
    </collision>
    <visual name="arm_2_link_4_visual">
      <geometry>
        <mesh filename="package://repair_urdf/meshes/link_4.stl" scale="0.001 0.001 0.001"/>
      </geometry>
      <material name="dark"/>
    </visual>
  </link>
  <link name="arm_2_link_5">
    <inertial>
      <mass value="0.1"/>
      <inertia ixx="0.0001" ixy="0" ixz="0" iyy="0.0001" iyz="0" izz="0.0001"/>
      <origin xyz="0 0 0"/>
    </inertial>
    <collision name="arm_2_link_5_collision">
      <geometry>
        <mesh filename="package://repair_urdf/meshes/link_5.stl" scale="0.001 0.001 0.001"/>
      </geometry>
      <material name="dark"/>
    </collision>
    <visual name="arm_2_link_5_visual">
      <geometry>
        <mesh filename="package://repair_urdf/meshes/link_5.stl" scale="0.001 0.001 0.001"/>
      </geometry>
      <material name="dark"/>
    </visual>
  </link>
  <link name="arm_2_link_6">
    <inertial>
      <mass value="0.1"/>
      <inertia ixx="0.0001" ixy="0" ixz="0" iyy="0.0001" iyz="0" izz="0.0001"/>
      <origin xyz="0 0 0"/>
    </inertial>
    <collision name="arm_2_link_6_collision">
      <geometry>
        <mesh filename="package://repair_urdf/meshes/link_6.stl" scale="0.001 0.001 0.001"/>
      </geometry>
      <material name="dark"/>
    </collision>
    <visual name="arm_2_link_6_visual">
      <geometry>
        <mesh filename="package://repair_urdf/meshes/link_6.stl" scale="0.001 0.001 0.001"/>
      </geometry>
      <material name="dark"/>
    </visual>
  </link>
  <link name="arm_2_link_7">
    <inertial>
      <mass value="0.1"/>
      <inertia ixx="0.0001" ixy="0" ixz="0" iyy="0.0001" iyz="0" izz="0.0001"/>
      <origin xyz="0 0 0"/>
    </inertial>
    <collision name="arm_2_link_7_collision">
      <geometry>
        <mesh filename="package://repair_urdf/meshes/link_7.stl" scale="0.001 0.001 0.001"/>
      </geometry>
      <material name="dark"/>
    </collision>
    <visual name="arm_2_link_7_visual">
      <geometry>
        <mesh filename="package://repair_urdf/meshes/link_7.stl" scale="0.001 0.001 0.001"/>
      </geometry>
      <material name="dark"/>
    </visual>
  </link>
  <link name="arm_2_tcp"/>
</robot>
