<?xml version="1.0" ?>
<!-- =================================================================================== -->
<!-- |    This document was autogenerated by xacro from repair_single_arm.urdf.xacro   | -->
<!-- |    EDITING THIS FILE BY HAND IS NOT RECOMMENDED                                 | -->
<!-- =================================================================================== -->
<robot name="repair">
  <!-- color -->
  <material name="darkblue">
    <color rgba="0.0 0.3 0.9 1"/>
  </material>
  <material name="dark">
    <color rgba="0.6 0.6 0.6 1"/>
  </material>
  <link name="world"/>
  <link name="base_link">
</link>
  <joint name="base_joint" type="fixed">
    <origin rpy="0 0 0" xyz="0 0 0.5"/>
    <parent link="world"/>
    <child link="base_link"/>
  </joint>
  <link name="r_arm_mount_frame">
</link>
  <joint name="r_arm_mount_joint" type="fixed">
    <origin rpy="1.57079632679 3.14159265359 0" xyz="0 -0.2 0"/>
    <parent link="base_link"/>
    <child link="r_arm_mount_frame"/>
  </joint>
  <joint name="arm_1_joint_1" type="revolute">
    <origin rpy="0 0 0" xyz="0 0 0"/>
    <parent link="r_arm_mount_frame"/>
    <child link="arm_1_link_1"/>
    <axis xyz="0 0 1"/>
    <limit effort="200.0" lower="-2.6179938779916667" upper="2.6179938779916667" velocity="10.0"/>
  </joint>
  <joint name="arm_1_joint_2" type="revolute">
    <origin rpy="0 -1.57079632679 3.14159265359" xyz="0.007 0 0"/>
    <parent link="arm_1_link_1"/>
    <child link="arm_1_link_2"/>
    <axis xyz="0 0 1"/>
    <limit effort="200.0" lower="-1.570796326795" upper="1.570796326795" velocity="10.0"/>
  </joint>
  <joint name="arm_1_joint_3" type="revolute">
    <origin rpy="0 -1.57079632679 3.14159265359" xyz="0 0 0"/>
    <parent link="arm_1_link_2"/>
    <child link="arm_1_link_3"/>
    <axis xyz="0 0 1"/>
    <limit effort="200.0" lower="-2.6179938779916667" upper="2.6179938779916667" velocity="10.0"/>
  </joint>
  <joint name="arm_1_joint_4" type="revolute">
    <origin rpy="0 -1.57079632679 3.14159265359" xyz="0 0.0225 0.36014999999999997"/>
    <parent link="arm_1_link_3"/>
    <child link="arm_1_link_4"/>
    <axis xyz="0 0 1"/>
    <limit effort="200.0" lower="-2.6179938779916667" upper="0.8726646259972222" velocity="10.0"/>
  </joint>
  <joint name="arm_1_joint_5" type="revolute">
    <origin rpy="0 -1.57079632679 3.14159265359" xyz="0 0 0"/>
    <parent link="arm_1_link_4"/>
    <child link="arm_1_link_5"/>
    <axis xyz="0 0 1"/>
    <limit effort="200.0" lower="-2.6179938779916667" upper="2.6179938779916667" velocity="10.0"/>
  </joint>
  <joint name="arm_1_joint_6" type="revolute">
    <origin rpy="0 -1.57079632679 3.14159265359" xyz="0 0 0.321"/>
    <parent link="arm_1_link_5"/>
    <child link="arm_1_link_6"/>
    <axis xyz="0 0 1"/>
    <limit effort="200.0" lower="-2.6179938779916667" upper="2.6179938779916667" velocity="10.0"/>
  </joint>
  <joint name="arm_1_joint_7" type="revolute">
    <origin rpy="0 -1.57079632679 3.14159265359" xyz="0.18 0 0"/>
    <parent link="arm_1_link_6"/>
    <child link="arm_1_link_7"/>
    <axis xyz="0 0 1"/>
    <limit effort="200.0" lower="-2.6179938779916667" upper="2.6179938779916667" velocity="10.0"/>
  </joint>
  <joint name="arm_1_tcp_joint" type="fixed">
    <origin rpy="0 0 0" xyz="0 0 0"/>
    <parent link="arm_1_link_7"/>
    <child link="arm_1_tcp"/>
  </joint>
  <link name="arm_1_link_1">
    <inertial>
      <mass value="0.1"/>
      <inertia ixx="0.0001" ixy="0" ixz="0" iyy="0.0001" iyz="0" izz="0.0001"/>
      <origin xyz="0 0 0"/>
    </inertial>
    <collision name="arm_1_link_1_collision">
      <geometry>
        <mesh filename="package://repair_urdf/meshes/link_1.stl" scale="0.001 0.001 0.001"/>
      </geometry>
      <material name="dark"/>
    </collision>
    <visual name="arm_1_link_1_visual">
      <geometry>
        <mesh filename="package://repair_urdf/meshes/link_1.stl" scale="0.001 0.001 0.001"/>
      </geometry>
      <material name="dark"/>
    </visual>
  </link>
  <link name="arm_1_link_2">
    <inertial>
      <mass value="0.1"/>
      <inertia ixx="0.0001" ixy="0" ixz="0" iyy="0.0001" iyz="0" izz="0.0001"/>
      <origin xyz="0 0 0"/>
    </inertial>
    <collision name="arm_1_link_2_collision">
      <geometry>
        <mesh filename="package://repair_urdf/meshes/link_2.stl" scale="0.001 0.001 0.001"/>
      </geometry>
      <material name="dark"/>
    </collision>
    <visual name="arm_1_link_2_visual">
      <geometry>
        <mesh filename="package://repair_urdf/meshes/link_2.stl" scale="0.001 0.001 0.001"/>
      </geometry>
      <material name="dark"/>
    </visual>
  </link>
  <link name="arm_1_link_3">
    <inertial>
      <mass value="0.1"/>
      <inertia ixx="0.0001" ixy="0" ixz="0" iyy="0.0001" iyz="0" izz="0.0001"/>
      <origin xyz="0 0 0"/>
    </inertial>
    <collision name="arm_1_link_3_collision">
      <geometry>
        <mesh filename="package://repair_urdf/meshes/link_3.stl" scale="0.001 0.001 0.001"/>
      </geometry>
      <material name="dark"/>
    </collision>
    <visual name="arm_1_link_3_visual">
      <geometry>
        <mesh filename="package://repair_urdf/meshes/link_3.stl" scale="0.001 0.001 0.001"/>
      </geometry>
      <material name="dark"/>
    </visual>
  </link>
  <link name="arm_1_link_4">
    <inertial>
      <mass value="0.1"/>
      <inertia ixx="0.0001" ixy="0" ixz="0" iyy="0.0001" iyz="0" izz="0.0001"/>
      <origin xyz="0 0 0"/>
    </inertial>
    <collision name="arm_1_link_4_collision">
      <geometry>
        <mesh filename="package://repair_urdf/meshes/link_4.stl" scale="0.001 0.001 0.001"/>
      </geometry>
      <material name="dark"/>
    </collision>
    <visual name="arm_1_link_4_visual">
      <geometry>
        <mesh filename="package://repair_urdf/meshes/link_4.stl" scale="0.001 0.001 0.001"/>
      </geometry>
      <material name="dark"/>
    </visual>
  </link>
  <link name="arm_1_link_5">
    <inertial>
      <mass value="0.1"/>
      <inertia ixx="0.0001" ixy="0" ixz="0" iyy="0.0001" iyz="0" izz="0.0001"/>
      <origin xyz="0 0 0"/>
    </inertial>
    <collision name="arm_1_link_5_collision">
      <geometry>
        <mesh filename="package://repair_urdf/meshes/link_5.stl" scale="0.001 0.001 0.001"/>
      </geometry>
      <material name="dark"/>
    </collision>
    <visual name="arm_1_link_5_visual">
      <geometry>
        <mesh filename="package://repair_urdf/meshes/link_5.stl" scale="0.001 0.001 0.001"/>
      </geometry>
      <material name="dark"/>
    </visual>
  </link>
  <link name="arm_1_link_6">
    <inertial>
      <mass value="0.1"/>
      <inertia ixx="0.0001" ixy="0" ixz="0" iyy="0.0001" iyz="0" izz="0.0001"/>
      <origin xyz="0 0 0"/>
    </inertial>
    <collision name="arm_1_link_6_collision">
      <geometry>
        <mesh filename="package://repair_urdf/meshes/link_6.stl" scale="0.001 0.001 0.001"/>
      </geometry>
      <material name="dark"/>
    </collision>
    <visual name="arm_1_link_6_visual">
      <geometry>
        <mesh filename="package://repair_urdf/meshes/link_6.stl" scale="0.001 0.001 0.001"/>
      </geometry>
      <material name="dark"/>
    </visual>
  </link>
  <link name="arm_1_link_7">
    <inertial>
      <mass value="0.1"/>
      <inertia ixx="0.0001" ixy="0" ixz="0" iyy="0.0001" iyz="0" izz="0.0001"/>
      <origin xyz="0 0 0"/>
    </inertial>
    <collision name="arm_1_link_7_collision">
      <geometry>
        <mesh filename="package://repair_urdf/meshes/link_7.stl" scale="0.001 0.001 0.001"/>
      </geometry>
      <material name="dark"/>
    </collision>
    <visual name="arm_1_link_7_visual">
      <geometry>
        <mesh filename="package://repair_urdf/meshes/link_7.stl" scale="0.001 0.001 0.001"/>
      </geometry>
      <material name="dark"/>
    </visual>
  </link>
  <link name="arm_1_tcp"/>
</robot>
